<?xml version="1.0" encoding="utf-8"?>
<robot name="osim_robot">
   <link name="pelvis">
      <inertial>
         <mass value="9.8484277313936062"/>
         <origin rpy="0 0 0" xyz="0 0 0"/>
         <inertia ixx="0.087336" ixy="0" ixz="0" iyy="0.073998" iyz="0" izz="0.04919"/>
      </inertial>
      <visual name="visual1">
         <geometry>
            <mesh filename="Geometry/r_pelvis.stl"
                  scale="1.0079389298149146 1.0079389298149146 1.0079389298149146"/>
         </geometry>
         <origin rpy="0 0 0" xyz="0 0 0"/>
         <material name="white">
            <color rgba="1 1 1 1"/>
         </material>
      </visual>
      <visual name="visual2">
         <geometry>
            <mesh filename="Geometry/l_pelvis.stl"
                  scale="1.0079389298149146 1.0079389298149146 1.0079389298149146"/>
         </geometry>
         <origin rpy="0 0 0" xyz="0 0 0"/>
         <material name="white">
            <color rgba="1 1 1 1"/>
         </material>
      </visual>
      <visual name="visual3">
         <geometry>
            <mesh filename="Geometry/sacrum.stl"
                  scale="1.0079389298149146 1.0079389298149146 1.0079389298149146"/>
         </geometry>
         <origin rpy="0 0 0" xyz="0 0 0"/>
         <material name="white">
            <color rgba="1 1 1 1"/>
         </material>
      </visual>
   </link>
   <link name="femur_r">
      <inertial>
         <mass value="7.7782258385653806"/>
         <origin rpy="0 0 0" xyz="0 0 0"/>
         <inertia ixx="0.096584" ixy="0" ixz="0" iyy="0.025318" iyz="0" izz="0.10185"/>
      </inertial>
      <visual name="visual1">
         <geometry>
            <mesh filename="Geometry/r_femur.stl"
                  scale="0.9287425461574641 0.9287425461574641 0.9287425461574641"/>
         </geometry>
         <origin rpy="0 0 0" xyz="0 0 0"/>
         <material name="white">
            <color rgba="1 1 1 1"/>
         </material>
      </visual>
      <collision>
         <origin rpy="1.57 0 0" xyz="0.000000 -0.185749 0.018575"/>
         <geometry>
            <capsule length="0.301841" radius="0.013931"/>
         </geometry>
      </collision>
   </link>
   <link name="tibia_r">
      <inertial>
         <mass value="3.1003690085880784"/>
         <origin rpy="0 0 0" xyz="0 0 0"/>
         <inertia ixx="0.048987" ixy="0" ixz="0" iyy="0.004957" iyz="0" izz="0.049667"/>
      </inertial>
      <visual name="visual1">
         <geometry>
            <mesh filename="Geometry/r_tibia.stl"
                  scale="1.0780959480072534 1.0780959480072534 1.0780959480072534"/>
         </geometry>
         <origin rpy="0 0 0" xyz="0 0 0"/>
         <material name="white">
            <color rgba="1 1 1 1"/>
         </material>
      </visual>
      <collision>
         <origin rpy="1.57 0 0" xyz="0.000000 -0.161714 0.021562"/>
         <geometry>
            <capsule length="0.296476" radius="0.016171"/>
         </geometry>
      </collision>
      <visual name="visual2">
         <geometry>
            <mesh filename="Geometry/r_fibula.stl"
                  scale="1.0780959480072534 1.0780959480072534 1.0780959480072534"/>
         </geometry>
         <origin rpy="0 0 0" xyz="0 0 0"/>
         <material name="white">
            <color rgba="1 1 1 1"/>
         </material>
      </visual>
      <collision>
         <origin rpy="1.57 0 0" xyz="0.000000 -0.161714 0.021562"/>
         <geometry>
            <capsule length="0.296476" radius="0.016171"/>
         </geometry>
      </collision>
   </link>
   <link name="patella_r">
      <inertial>
         <mass value="0.072084102101225178"/>
         <origin rpy="0 0 0" xyz="0 0 0"/>
         <inertia ixx="2.0702e-06" ixy="0" ixz="0" iyy="9.4564e-06" iyz="0" izz="9.4564e-06"/>
      </inertial>
   </link>
   <link name="talus_r">
      <inertial>
         <mass value="0.083624248377291391"/>
         <origin rpy="0 0 0" xyz="0 0 0"/>
         <inertia ixx="0.00097196" ixy="0" ixz="0" iyy="0.00097196" iyz="0" izz="0.00097196"/>
      </inertial>
      <visual name="visual1">
         <geometry>
            <mesh filename="Geometry/r_talus.stl"
                  scale="1.0780959480072534 1.0780959480072534 1.0780959480072534"/>
         </geometry>
         <origin rpy="0 0 0" xyz="0 0 0"/>
         <material name="white">
            <color rgba="1 1 1 1"/>
         </material>
      </visual>
   </link>
   <link name="calcn_r">
      <inertial>
         <mass value="1.0453031047161423"/>
         <origin rpy="0 0 0" xyz="0 0 0"/>
         <inertia ixx="0.00092502" ixy="0" ixz="0" iyy="0.0025768" iyz="0" izz="0.002709"/>
      </inertial>
      <visual name="visual1">
         <geometry>
            <mesh filename="Geometry/r_foot.stl"
                  scale="0.88888589868301748 0.88888589868301748 0.88888589868301748"/>
         </geometry>
         <origin rpy="0 0 0" xyz="0 0 0"/>
         <material name="white">
            <color rgba="1 1 1 1"/>
         </material>
      </visual>
      <collision>
         <origin rpy="0 0 0" xyz="0.026667 0.017778 0.000000"/>
         <geometry>
            <sphere radius="0.044444"/>
         </geometry>
      </collision>
   </link>
   <link name="toes_r">
      <inertial>
         <mass value="0.18113012198521314"/>
         <origin rpy="0 0 0" xyz="0 0 0"/>
         <inertia ixx="6.6073e-05" ixy="0" ixz="0" iyy="0.00013215" iyz="0" izz="0.00066073"/>
      </inertial>
      <visual name="visual1">
         <geometry>
            <mesh filename="Geometry/r_bofoot.stl"
                  scale="0.88888589868301748 0.88888589868301748 0.88888589868301748"/>
         </geometry>
         <origin rpy="0 0 0" xyz="0 0 0"/>
         <material name="white">
            <color rgba="1 1 1 1"/>
         </material>
      </visual>
      <collision>
         <origin rpy="0 0 0" xyz="0.017778 -0.004444 -0.023111"/>
         <geometry>
            <sphere radius="0.022222"/>
         </geometry>
      </collision>
      <collision>
         <origin rpy="0 0 0" xyz="0.017778 -0.004444 0.023111"/>
         <geometry>
            <sphere radius="0.022222"/>
         </geometry>
      </collision>
   </link>
   <link name="femur_l">
      <inertial>
         <mass value="7.7782258385653806"/>
         <origin rpy="0 0 0" xyz="0 0 0"/>
         <inertia ixx="0.096584" ixy="0" ixz="0" iyy="0.025318" iyz="0" izz="0.10185"/>
      </inertial>
      <visual name="visual1">
         <geometry>
            <mesh filename="Geometry/l_femur.stl"
                  scale="0.9287425461574641 0.9287425461574641 0.9287425461574641"/>
         </geometry>
         <origin rpy="0 0 0" xyz="0 0 0"/>
         <material name="white">
            <color rgba="1 1 1 1"/>
         </material>
      </visual>
      <collision>
         <origin rpy="1.57 0 0" xyz="0.000000 -0.185749 -0.018575"/>
         <geometry>
            <capsule length="0.301841" radius="0.013931"/>
         </geometry>
      </collision>
   </link>
   <link name="tibia_l">
      <inertial>
         <mass value="3.1003690085880784"/>
         <origin rpy="0 0 0" xyz="0 0 0"/>
         <inertia ixx="0.048987" ixy="0" ixz="0" iyy="0.004957" iyz="0" izz="0.049667"/>
      </inertial>
      <visual name="visual1">
         <geometry>
            <mesh filename="Geometry/l_tibia.stl"
                  scale="1.0780959480072534 1.0780959480072534 1.0780959480072534"/>
         </geometry>
         <origin rpy="0 0 0" xyz="0 0 0"/>
         <material name="white">
            <color rgba="1 1 1 1"/>
         </material>
      </visual>
      <collision>
         <origin rpy="1.57 0 0" xyz="0.000000 -0.161714 -0.021562"/>
         <geometry>
            <capsule length="0.296476" radius="0.016171"/>
         </geometry>
      </collision>
      <visual name="visual2">
         <geometry>
            <mesh filename="Geometry/l_fibula.stl"
                  scale="1.0780959480072534 1.0780959480072534 1.0780959480072534"/>
         </geometry>
         <origin rpy="0 0 0" xyz="0 0 0"/>
         <material name="white">
            <color rgba="1 1 1 1"/>
         </material>
      </visual>
      <collision>
         <origin rpy="1.57 0 0" xyz="0.000000 -0.161714 -0.021562"/>
         <geometry>
            <capsule length="0.296476" radius="0.016171"/>
         </geometry>
      </collision>
   </link>
   <link name="patella_l">
      <inertial>
         <mass value="0.072084102101225178"/>
         <origin rpy="0 0 0" xyz="0 0 0"/>
         <inertia ixx="2.0702e-06" ixy="0" ixz="0" iyy="9.4564e-06" iyz="0" izz="9.4564e-06"/>
      </inertial>
   </link>
   <link name="talus_l">
      <inertial>
         <mass value="0.083624248377291391"/>
         <origin rpy="0 0 0" xyz="0 0 0"/>
         <inertia ixx="0.00097196" ixy="0" ixz="0" iyy="0.00097196" iyz="0" izz="0.00097196"/>
      </inertial>
      <visual name="visual1">
         <geometry>
            <mesh filename="Geometry/l_talus.stl"
                  scale="1.0780959480072534 1.0780959480072534 1.0780959480072534"/>
         </geometry>
         <origin rpy="0 0 0" xyz="0 0 0"/>
         <material name="white">
            <color rgba="1 1 1 1"/>
         </material>
      </visual>
   </link>
   <link name="calcn_l">
      <inertial>
         <mass value="1.0453031047161423"/>
         <origin rpy="0 0 0" xyz="0 0 0"/>
         <inertia ixx="0.00092502" ixy="0" ixz="0" iyy="0.0025768" iyz="0" izz="0.002709"/>
      </inertial>
      <visual name="visual1">
         <geometry>
            <mesh filename="Geometry/l_foot.stl"
                  scale="0.88888589868301748 0.88888589868301748 0.88888589868301748"/>
         </geometry>
         <origin rpy="0 0 0" xyz="0 0 0"/>
         <material name="white">
            <color rgba="1 1 1 1"/>
         </material>
      </visual>
      <collision>
         <origin rpy="0 0 0" xyz="0.026667 0.017778 0.000000"/>
         <geometry>
            <sphere radius="0.044444"/>
         </geometry>
      </collision>
   </link>
   <link name="toes_l">
      <inertial>
         <mass value="0.18113012198521314"/>
         <origin rpy="0 0 0" xyz="0 0 0"/>
         <inertia ixx="6.6073e-05" ixy="0" ixz="0" iyy="0.00013215" iyz="0" izz="0.00066073"/>
      </inertial>
      <visual name="visual1">
         <geometry>
            <mesh filename="Geometry/l_bofoot.stl"
                  scale="0.88888589868301748 0.88888589868301748 0.88888589868301748"/>
         </geometry>
         <origin rpy="0 0 0" xyz="0 0 0"/>
         <material name="white">
            <color rgba="1 1 1 1"/>
         </material>
      </visual>
      <collision>
         <origin rpy="0 0 0" xyz="0.017778 -0.004444 -0.023111"/>
         <geometry>
            <sphere radius="0.022222"/>
         </geometry>
      </collision>
      <collision>
         <origin rpy="0 0 0" xyz="0.017778 -0.004444 0.023111"/>
         <geometry>
            <sphere radius="0.022222"/>
         </geometry>
      </collision>
   </link>
   <link name="torso">
      <inertial>
         <mass value="22.43354261518245"/>
         <origin rpy="0 0 0" xyz="0 0 0"/>
         <inertia ixx="1.2795" ixy="0" ixz="0" iyy="0.65557" iyz="0" izz="1.2421"/>
      </inertial>
      <visual name="visual1">
         <geometry>
            <mesh filename="Geometry/hat_spine.stl"
                  scale="1.0186550220494073 1.0186550220494073 1.0186550220494073"/>
         </geometry>
         <origin rpy="0 0 0" xyz="0 0 0"/>
         <material name="white">
            <color rgba="1 1 1 1"/>
         </material>
      </visual>
      <visual name="visual2">
         <geometry>
            <mesh filename="Geometry/hat_jaw.stl"
                  scale="1.0186550220494073 1.0186550220494073 1.0186550220494073"/>
         </geometry>
         <origin rpy="0 0 0" xyz="0 0 0"/>
         <material name="white">
            <color rgba="1 1 1 1"/>
         </material>
      </visual>
      <visual name="visual3">
         <geometry>
            <mesh filename="Geometry/hat_skull.stl"
                  scale="1.0186550220494073 1.0186550220494073 1.0186550220494073"/>
         </geometry>
         <origin rpy="0 0 0" xyz="0 0 0"/>
         <material name="white">
            <color rgba="1 1 1 1"/>
         </material>
      </visual>
      <visual name="visual4">
         <geometry>
            <mesh filename="Geometry/hat_ribs_scap.stl"
                  scale="1.0186550220494073 1.0186550220494073 1.0186550220494073"/>
         </geometry>
         <origin rpy="0 0 0" xyz="0 0 0"/>
         <material name="white">
            <color rgba="1 1 1 1"/>
         </material>
      </visual>
   </link>
   <link name="humerus_r">
      <inertial>
         <mass value="1.6996628482684477"/>
         <origin rpy="0 0 0" xyz="0 0 0"/>
         <inertia ixx="0.0099898" ixy="0" ixz="0" iyy="0.0034462" iyz="0" izz="0.011213"/>
      </inertial>
      <visual name="visual1">
         <geometry>
            <mesh filename="Geometry/humerus_rv.stl" scale="1 1 1"/>
         </geometry>
         <origin rpy="0 0 0" xyz="0 0 0"/>
         <material name="white">
            <color rgba="1 1 1 1"/>
         </material>
      </visual>
   </link>
   <link name="ulna_r">
      <inertial>
         <mass value="0.50801730889204522"/>
         <origin rpy="0 0 0" xyz="0 0 0"/>
         <inertia ixx="0.002477" ixy="0" ixz="0" iyy="0.0005168" iyz="0" izz="0.0026868"/>
      </inertial>
      <visual name="visual1">
         <geometry>
            <mesh filename="Geometry/ulna_rv.stl" scale="1 1 1"/>
         </geometry>
         <origin rpy="0 0 0" xyz="0 0 0"/>
         <material name="white">
            <color rgba="1 1 1 1"/>
         </material>
      </visual>
   </link>
   <link name="radius_r">
      <inertial>
         <mass value="0.50801730889204522"/>
         <origin rpy="0 0 0" xyz="0 0 0"/>
         <inertia ixx="0.002477" ixy="0" ixz="0" iyy="0.0005168" iyz="0" izz="0.0026868"/>
      </inertial>
      <visual name="visual1">
         <geometry>
            <mesh filename="Geometry/radius_rv.stl" scale="1 1 1"/>
         </geometry>
         <origin rpy="0 0 0" xyz="0 0 0"/>
         <material name="white">
            <color rgba="1 1 1 1"/>
         </material>
      </visual>
   </link>
   <link name="hand_r">
      <inertial>
         <mass value="0.38258093632610812"/>
         <origin rpy="0 0 0" xyz="0 0 0"/>
         <inertia ixx="0.00074593" ixy="0" ixz="0" iyy="0.00045742" iyz="0" izz="0.0011206"/>
      </inertial>
      <visual name="visual1">
         <geometry>
            <mesh filename="Geometry/pisiform_rvs.stl"
                  scale="0.84999999999999998 0.84999999999999998 0.84999999999999998"/>
         </geometry>
         <origin rpy="0 0 0" xyz="0 0 0"/>
         <material name="white">
            <color rgba="1 1 1 1"/>
         </material>
      </visual>
      <visual name="visual2">
         <geometry>
            <mesh filename="Geometry/lunate_rvs.stl"
                  scale="0.84999999999999998 0.84999999999999998 0.84999999999999998"/>
         </geometry>
         <origin rpy="0 0 0" xyz="0 0 0"/>
         <material name="white">
            <color rgba="1 1 1 1"/>
         </material>
      </visual>
      <visual name="visual3">
         <geometry>
            <mesh filename="Geometry/scaphoid_rvs.stl"
                  scale="0.84999999999999998 0.84999999999999998 0.84999999999999998"/>
         </geometry>
         <origin rpy="0 0 0" xyz="0 0 0"/>
         <material name="white">
            <color rgba="1 1 1 1"/>
         </material>
      </visual>
      <visual name="visual4">
         <geometry>
            <mesh filename="Geometry/triquetrum_rvs.stl"
                  scale="0.84999999999999998 0.84999999999999998 0.84999999999999998"/>
         </geometry>
         <origin rpy="0 0 0" xyz="0 0 0"/>
         <material name="white">
            <color rgba="1 1 1 1"/>
         </material>
      </visual>
      <visual name="visual5">
         <geometry>
            <mesh filename="Geometry/hamate_rvs.stl"
                  scale="0.84999999999999998 0.84999999999999998 0.84999999999999998"/>
         </geometry>
         <origin rpy="0 0 0" xyz="0 0 0"/>
         <material name="white">
            <color rgba="1 1 1 1"/>
         </material>
      </visual>
      <visual name="visual6">
         <geometry>
            <mesh filename="Geometry/capitate_rvs.stl"
                  scale="0.84999999999999998 0.84999999999999998 0.84999999999999998"/>
         </geometry>
         <origin rpy="0 0 0" xyz="0 0 0"/>
         <material name="white">
            <color rgba="1 1 1 1"/>
         </material>
      </visual>
      <visual name="visual7">
         <geometry>
            <mesh filename="Geometry/trapezoid_rvs.stl"
                  scale="0.84999999999999998 0.84999999999999998 0.84999999999999998"/>
         </geometry>
         <origin rpy="0 0 0" xyz="0 0 0"/>
         <material name="white">
            <color rgba="1 1 1 1"/>
         </material>
      </visual>
      <visual name="visual8">
         <geometry>
            <mesh filename="Geometry/trapezium_rvs.stl"
                  scale="0.84999999999999998 0.84999999999999998 0.84999999999999998"/>
         </geometry>
         <origin rpy="0 0 0" xyz="0 0 0"/>
         <material name="white">
            <color rgba="1 1 1 1"/>
         </material>
      </visual>
      <visual name="visual9">
         <geometry>
            <mesh filename="Geometry/metacarpal2_rvs.stl"
                  scale="0.84999999999999998 0.84999999999999998 0.84999999999999998"/>
         </geometry>
         <origin rpy="0 0 0" xyz="0 0 0"/>
         <material name="white">
            <color rgba="1 1 1 1"/>
         </material>
      </visual>
      <visual name="visual10">
         <geometry>
            <mesh filename="Geometry/index_proximal_rvs.stl"
                  scale="0.84999999999999998 0.84999999999999998 0.84999999999999998"/>
         </geometry>
         <origin rpy="0 0 0" xyz="0 0 0"/>
         <material name="white">
            <color rgba="1 1 1 1"/>
         </material>
      </visual>
      <visual name="visual11">
         <geometry>
            <mesh filename="Geometry/index_medial_rvs.stl"
                  scale="0.84999999999999998 0.84999999999999998 0.84999999999999998"/>
         </geometry>
         <origin rpy="0 0 0" xyz="0 0 0"/>
         <material name="white">
            <color rgba="1 1 1 1"/>
         </material>
      </visual>
      <visual name="visual12">
         <geometry>
            <mesh filename="Geometry/index_distal_rvs.stl"
                  scale="0.84999999999999998 0.84999999999999998 0.84999999999999998"/>
         </geometry>
         <origin rpy="0 0 0" xyz="0 0 0"/>
         <material name="white">
            <color rgba="1 1 1 1"/>
         </material>
      </visual>
      <visual name="visual13">
         <geometry>
            <mesh filename="Geometry/metacarpal3_rvs.stl"
                  scale="0.84999999999999998 0.84999999999999998 0.84999999999999998"/>
         </geometry>
         <origin rpy="0 0 0" xyz="0 0 0"/>
         <material name="white">
            <color rgba="1 1 1 1"/>
         </material>
      </visual>
      <visual name="visual14">
         <geometry>
            <mesh filename="Geometry/middle_proximal_rvs.stl"
                  scale="0.84999999999999998 0.84999999999999998 0.84999999999999998"/>
         </geometry>
         <origin rpy="0 0 0" xyz="0 0 0"/>
         <material name="white">
            <color rgba="1 1 1 1"/>
         </material>
      </visual>
      <visual name="visual15">
         <geometry>
            <mesh filename="Geometry/middle_medial_rvs.stl"
                  scale="0.84999999999999998 0.84999999999999998 0.84999999999999998"/>
         </geometry>
         <origin rpy="0 0 0" xyz="0 0 0"/>
         <material name="white">
            <color rgba="1 1 1 1"/>
         </material>
      </visual>
      <visual name="visual16">
         <geometry>
            <mesh filename="Geometry/middle_distal_rvs.stl"
                  scale="0.84999999999999998 0.84999999999999998 0.84999999999999998"/>
         </geometry>
         <origin rpy="0 0 0" xyz="0 0 0"/>
         <material name="white">
            <color rgba="1 1 1 1"/>
         </material>
      </visual>
      <visual name="visual17">
         <geometry>
            <mesh filename="Geometry/metacarpal4_rvs.stl"
                  scale="0.84999999999999998 0.84999999999999998 0.84999999999999998"/>
         </geometry>
         <origin rpy="0 0 0" xyz="0 0 0"/>
         <material name="white">
            <color rgba="1 1 1 1"/>
         </material>
      </visual>
      <visual name="visual18">
         <geometry>
            <mesh filename="Geometry/ring_proximal_rvs.stl"
                  scale="0.84999999999999998 0.84999999999999998 0.84999999999999998"/>
         </geometry>
         <origin rpy="0 0 0" xyz="0 0 0"/>
         <material name="white">
            <color rgba="1 1 1 1"/>
         </material>
      </visual>
      <visual name="visual19">
         <geometry>
            <mesh filename="Geometry/ring_medial_rvs.stl"
                  scale="0.84999999999999998 0.84999999999999998 0.84999999999999998"/>
         </geometry>
         <origin rpy="0 0 0" xyz="0 0 0"/>
         <material name="white">
            <color rgba="1 1 1 1"/>
         </material>
      </visual>
      <visual name="visual20">
         <geometry>
            <mesh filename="Geometry/ring_distal_rvs.stl"
                  scale="0.84999999999999998 0.84999999999999998 0.84999999999999998"/>
         </geometry>
         <origin rpy="0 0 0" xyz="0 0 0"/>
         <material name="white">
            <color rgba="1 1 1 1"/>
         </material>
      </visual>
      <visual name="visual21">
         <geometry>
            <mesh filename="Geometry/metacarpal5_rvs.stl"
                  scale="0.84999999999999998 0.84999999999999998 0.84999999999999998"/>
         </geometry>
         <origin rpy="0 0 0" xyz="0 0 0"/>
         <material name="white">
            <color rgba="1 1 1 1"/>
         </material>
      </visual>
      <visual name="visual22">
         <geometry>
            <mesh filename="Geometry/little_proximal_rvs.stl"
                  scale="0.84999999999999998 0.84999999999999998 0.84999999999999998"/>
         </geometry>
         <origin rpy="0 0 0" xyz="0 0 0"/>
         <material name="white">
            <color rgba="1 1 1 1"/>
         </material>
      </visual>
      <visual name="visual23">
         <geometry>
            <mesh filename="Geometry/little_medial_rvs.stl"
                  scale="0.84999999999999998 0.84999999999999998 0.84999999999999998"/>
         </geometry>
         <origin rpy="0 0 0" xyz="0 0 0"/>
         <material name="white">
            <color rgba="1 1 1 1"/>
         </material>
      </visual>
      <visual name="visual24">
         <geometry>
            <mesh filename="Geometry/little_distal_rvs.stl"
                  scale="0.84999999999999998 0.84999999999999998 0.84999999999999998"/>
         </geometry>
         <origin rpy="0 0 0" xyz="0 0 0"/>
         <material name="white">
            <color rgba="1 1 1 1"/>
         </material>
      </visual>
      <visual name="visual25">
         <geometry>
            <mesh filename="Geometry/metacarpal1_rvs.stl"
                  scale="0.84999999999999998 0.84999999999999998 0.84999999999999998"/>
         </geometry>
         <origin rpy="0 0 0" xyz="0 0 0"/>
         <material name="white">
            <color rgba="1 1 1 1"/>
         </material>
      </visual>
      <visual name="visual26">
         <geometry>
            <mesh filename="Geometry/thumb_proximal_rvs.stl"
                  scale="0.84999999999999998 0.84999999999999998 0.84999999999999998"/>
         </geometry>
         <origin rpy="0 0 0" xyz="0 0 0"/>
         <material name="white">
            <color rgba="1 1 1 1"/>
         </material>
      </visual>
      <visual name="visual27">
         <geometry>
            <mesh filename="Geometry/thumb_distal_rvs.stl"
                  scale="0.84999999999999998 0.84999999999999998 0.84999999999999998"/>
         </geometry>
         <origin rpy="0 0 0" xyz="0 0 0"/>
         <material name="white">
            <color rgba="1 1 1 1"/>
         </material>
      </visual>
   </link>
   <link name="humerus_l">
      <inertial>
         <mass value="1.6996628482684477"/>
         <origin rpy="0 0 0" xyz="0 0 0"/>
         <inertia ixx="0.0099898" ixy="0" ixz="0" iyy="0.0034462" iyz="0" izz="0.011213"/>
      </inertial>
      <visual name="visual1">
         <geometry>
            <mesh filename="Geometry/humerus_lv.stl" scale="1 1 1"/>
         </geometry>
         <origin rpy="0 0 0" xyz="0 0 0"/>
         <material name="white">
            <color rgba="1 1 1 1"/>
         </material>
      </visual>
   </link>
   <link name="ulna_l">
      <inertial>
         <mass value="0.50801730889204522"/>
         <origin rpy="0 0 0" xyz="0 0 0"/>
         <inertia ixx="0.002477" ixy="0" ixz="0" iyy="0.0005168" iyz="0" izz="0.0026868"/>
      </inertial>
      <visual name="visual1">
         <geometry>
            <mesh filename="Geometry/ulna_lv.stl" scale="1 1 1"/>
         </geometry>
         <origin rpy="0 0 0" xyz="0 0 0"/>
         <material name="white">
            <color rgba="1 1 1 1"/>
         </material>
      </visual>
   </link>
   <link name="radius_l">
      <inertial>
         <mass value="0.50801730889204522"/>
         <origin rpy="0 0 0" xyz="0 0 0"/>
         <inertia ixx="0.002477" ixy="0" ixz="0" iyy="0.0005168" iyz="0" izz="0.0026868"/>
      </inertial>
      <visual name="visual1">
         <geometry>
            <mesh filename="Geometry/radius_lv.stl" scale="1 1 1"/>
         </geometry>
         <origin rpy="0 0 0" xyz="0 0 0"/>
         <material name="white">
            <color rgba="1 1 1 1"/>
         </material>
      </visual>
   </link>
   <link name="hand_l">
      <inertial>
         <mass value="0.38258093632610812"/>
         <origin rpy="0 0 0" xyz="0 0 0"/>
         <inertia ixx="0.00074593" ixy="0" ixz="0" iyy="0.00045742" iyz="0" izz="0.0011206"/>
      </inertial>
      <visual name="visual1">
         <geometry>
            <mesh filename="Geometry/pisiform_lvs.stl"
                  scale="0.84999999999999998 0.84999999999999998 0.84999999999999998"/>
         </geometry>
         <origin rpy="0 0 0" xyz="0 0 0"/>
         <material name="white">
            <color rgba="1 1 1 1"/>
         </material>
      </visual>
      <visual name="visual2">
         <geometry>
            <mesh filename="Geometry/lunate_lvs.stl"
                  scale="0.84999999999999998 0.84999999999999998 0.84999999999999998"/>
         </geometry>
         <origin rpy="0 0 0" xyz="0 0 0"/>
         <material name="white">
            <color rgba="1 1 1 1"/>
         </material>
      </visual>
      <visual name="visual3">
         <geometry>
            <mesh filename="Geometry/scaphoid_lvs.stl"
                  scale="0.84999999999999998 0.84999999999999998 0.84999999999999998"/>
         </geometry>
         <origin rpy="0 0 0" xyz="0 0 0"/>
         <material name="white">
            <color rgba="1 1 1 1"/>
         </material>
      </visual>
      <visual name="visual4">
         <geometry>
            <mesh filename="Geometry/triquetrum_lvs.stl"
                  scale="0.84999999999999998 0.84999999999999998 0.84999999999999998"/>
         </geometry>
         <origin rpy="0 0 0" xyz="0 0 0"/>
         <material name="white">
            <color rgba="1 1 1 1"/>
         </material>
      </visual>
      <visual name="visual5">
         <geometry>
            <mesh filename="Geometry/hamate_lvs.stl"
                  scale="0.84999999999999998 0.84999999999999998 0.84999999999999998"/>
         </geometry>
         <origin rpy="0 0 0" xyz="0 0 0"/>
         <material name="white">
            <color rgba="1 1 1 1"/>
         </material>
      </visual>
      <visual name="visual6">
         <geometry>
            <mesh filename="Geometry/capitate_lvs.stl"
                  scale="0.84999999999999998 0.84999999999999998 0.84999999999999998"/>
         </geometry>
         <origin rpy="0 0 0" xyz="0 0 0"/>
         <material name="white">
            <color rgba="1 1 1 1"/>
         </material>
      </visual>
      <visual name="visual7">
         <geometry>
            <mesh filename="Geometry/trapezoid_lvs.stl"
                  scale="0.84999999999999998 0.84999999999999998 0.84999999999999998"/>
         </geometry>
         <origin rpy="0 0 0" xyz="0 0 0"/>
         <material name="white">
            <color rgba="1 1 1 1"/>
         </material>
      </visual>
      <visual name="visual8">
         <geometry>
            <mesh filename="Geometry/trapezium_lvs.stl"
                  scale="0.84999999999999998 0.84999999999999998 0.84999999999999998"/>
         </geometry>
         <origin rpy="0 0 0" xyz="0 0 0"/>
         <material name="white">
            <color rgba="1 1 1 1"/>
         </material>
      </visual>
      <visual name="visual9">
         <geometry>
            <mesh filename="Geometry/metacarpal2_lvs.stl"
                  scale="0.84999999999999998 0.84999999999999998 0.84999999999999998"/>
         </geometry>
         <origin rpy="0 0 0" xyz="0 0 0"/>
         <material name="white">
            <color rgba="1 1 1 1"/>
         </material>
      </visual>
      <visual name="visual10">
         <geometry>
            <mesh filename="Geometry/index_proximal_lvs.stl"
                  scale="0.84999999999999998 0.84999999999999998 0.84999999999999998"/>
         </geometry>
         <origin rpy="0 0 0" xyz="0 0 0"/>
         <material name="white">
            <color rgba="1 1 1 1"/>
         </material>
      </visual>
      <visual name="visual11">
         <geometry>
            <mesh filename="Geometry/index_medial_lvs.stl"
                  scale="0.84999999999999998 0.84999999999999998 0.84999999999999998"/>
         </geometry>
         <origin rpy="0 0 0" xyz="0 0 0"/>
         <material name="white">
            <color rgba="1 1 1 1"/>
         </material>
      </visual>
      <visual name="visual12">
         <geometry>
            <mesh filename="Geometry/index_distal_lvs.stl"
                  scale="0.84999999999999998 0.84999999999999998 0.84999999999999998"/>
         </geometry>
         <origin rpy="0 0 0" xyz="0 0 0"/>
         <material name="white">
            <color rgba="1 1 1 1"/>
         </material>
      </visual>
      <visual name="visual13">
         <geometry>
            <mesh filename="Geometry/metacarpal3_lvs.stl"
                  scale="0.84999999999999998 0.84999999999999998 0.84999999999999998"/>
         </geometry>
         <origin rpy="0 0 0" xyz="0 0 0"/>
         <material name="white">
            <color rgba="1 1 1 1"/>
         </material>
      </visual>
      <visual name="visual14">
         <geometry>
            <mesh filename="Geometry/middle_proximal_lvs.stl"
                  scale="0.84999999999999998 0.84999999999999998 0.84999999999999998"/>
         </geometry>
         <origin rpy="0 0 0" xyz="0 0 0"/>
         <material name="white">
            <color rgba="1 1 1 1"/>
         </material>
      </visual>
      <visual name="visual15">
         <geometry>
            <mesh filename="Geometry/middle_medial_lvs.stl"
                  scale="0.84999999999999998 0.84999999999999998 0.84999999999999998"/>
         </geometry>
         <origin rpy="0 0 0" xyz="0 0 0"/>
         <material name="white">
            <color rgba="1 1 1 1"/>
         </material>
      </visual>
      <visual name="visual16">
         <geometry>
            <mesh filename="Geometry/middle_distal_lvs.stl"
                  scale="0.84999999999999998 0.84999999999999998 0.84999999999999998"/>
         </geometry>
         <origin rpy="0 0 0" xyz="0 0 0"/>
         <material name="white">
            <color rgba="1 1 1 1"/>
         </material>
      </visual>
      <visual name="visual17">
         <geometry>
            <mesh filename="Geometry/metacarpal4_lvs.stl"
                  scale="0.84999999999999998 0.84999999999999998 0.84999999999999998"/>
         </geometry>
         <origin rpy="0 0 0" xyz="0 0 0"/>
         <material name="white">
            <color rgba="1 1 1 1"/>
         </material>
      </visual>
      <visual name="visual18">
         <geometry>
            <mesh filename="Geometry/ring_proximal_lvs.stl"
                  scale="0.84999999999999998 0.84999999999999998 0.84999999999999998"/>
         </geometry>
         <origin rpy="0 0 0" xyz="0 0 0"/>
         <material name="white">
            <color rgba="1 1 1 1"/>
         </material>
      </visual>
      <visual name="visual19">
         <geometry>
            <mesh filename="Geometry/ring_medial_lvs.stl"
                  scale="0.84999999999999998 0.84999999999999998 0.84999999999999998"/>
         </geometry>
         <origin rpy="0 0 0" xyz="0 0 0"/>
         <material name="white">
            <color rgba="1 1 1 1"/>
         </material>
      </visual>
      <visual name="visual20">
         <geometry>
            <mesh filename="Geometry/ring_distal_lvs.stl"
                  scale="0.84999999999999998 0.84999999999999998 0.84999999999999998"/>
         </geometry>
         <origin rpy="0 0 0" xyz="0 0 0"/>
         <material name="white">
            <color rgba="1 1 1 1"/>
         </material>
      </visual>
      <visual name="visual21">
         <geometry>
            <mesh filename="Geometry/metacarpal5_lvs.stl"
                  scale="0.84999999999999998 0.84999999999999998 0.84999999999999998"/>
         </geometry>
         <origin rpy="0 0 0" xyz="0 0 0"/>
         <material name="white">
            <color rgba="1 1 1 1"/>
         </material>
      </visual>
      <visual name="visual22">
         <geometry>
            <mesh filename="Geometry/little_proximal_lvs.stl"
                  scale="0.84999999999999998 0.84999999999999998 0.84999999999999998"/>
         </geometry>
         <origin rpy="0 0 0" xyz="0 0 0"/>
         <material name="white">
            <color rgba="1 1 1 1"/>
         </material>
      </visual>
      <visual name="visual23">
         <geometry>
            <mesh filename="Geometry/little_medial_lvs.stl"
                  scale="0.84999999999999998 0.84999999999999998 0.84999999999999998"/>
         </geometry>
         <origin rpy="0 0 0" xyz="0 0 0"/>
         <material name="white">
            <color rgba="1 1 1 1"/>
         </material>
      </visual>
      <visual name="visual24">
         <geometry>
            <mesh filename="Geometry/little_distal_lvs.stl"
                  scale="0.84999999999999998 0.84999999999999998 0.84999999999999998"/>
         </geometry>
         <origin rpy="0 0 0" xyz="0 0 0"/>
         <material name="white">
            <color rgba="1 1 1 1"/>
         </material>
      </visual>
      <visual name="visual25">
         <geometry>
            <mesh filename="Geometry/metacarpal1_lvs.stl"
                  scale="0.84999999999999998 0.84999999999999998 0.84999999999999998"/>
         </geometry>
         <origin rpy="0 0 0" xyz="0 0 0"/>
         <material name="white">
            <color rgba="1 1 1 1"/>
         </material>
      </visual>
      <visual name="visual26">
         <geometry>
            <mesh filename="Geometry/thumb_proximal_lvs.stl"
                  scale="0.84999999999999998 0.84999999999999998 0.84999999999999998"/>
         </geometry>
         <origin rpy="0 0 0" xyz="0 0 0"/>
         <material name="white">
            <color rgba="1 1 1 1"/>
         </material>
      </visual>
      <visual name="visual27">
         <geometry>
            <mesh filename="Geometry/thumb_distal_lvs.stl"
                  scale="0.84999999999999998 0.84999999999999998 0.84999999999999998"/>
         </geometry>
         <origin rpy="0 0 0" xyz="0 0 0"/>
         <material name="white">
            <color rgba="1 1 1 1"/>
         </material>
      </visual>
   </link>
   <joint name="back" type="spherical">
      <origin rpy="0. 0. 0." xyz="-0.101499 0.082147 0.000000"/>
      <parent link="pelvis"/>
      <child link="torso"/>
      <axis xyz="0 0 1"/>
      <limit effort="400" lower="1.57"/>
   </joint>
   <joint name="acromial_r" type="spherical">
      <origin rpy="0. 0. 0." xyz="0.003214 0.378430 0.173171"/>
      <parent link="torso"/>
      <child link="humerus_r"/>
      <axis xyz="0 0 1"/>
      <limit effort="100" lower="1.57"/>
   </joint>
   <joint name="elbow_r" type="revolute">
      <origin rpy="0. 0. 0." xyz="0.013144 -0.286273 -0.009595"/>
      <parent link="humerus_r"/>
      <child link="ulna_r"/>
      <axis xyz="0 0 1"/>
      <limit effort="100" lower="0" upper="3.0"/>
   </joint>
   <joint name="radioulnar_r" type="fixed">
      <origin rpy="0. 1.57 0." xyz="-0.006727 -0.013007 0.026083"/>
      <parent link="ulna_r"/>
      <child link="radius_r"/>
   </joint>
   <joint name="radius_hand_r" type="fixed">
      <origin rpy="0. 0. 0." xyz="-0.008797 -0.235841 0.013610"/>
      <parent link="radius_r"/>
      <child link="hand_r"/>
   </joint>
   <joint name="acromial_l" type="spherical">
      <origin rpy="0. 0. 0." xyz="0.003214 0.378430 -0.173171"/>
      <parent link="torso"/>
      <child link="humerus_l"/>
      <axis xyz="0 0 1"/>
      <limit effort="100" lower="1.57"/>
   </joint>
   <joint name="elbow_l" type="revolute">
      <origin rpy="0. 0. 0." xyz="0.013144 -0.286273 0.009595"/>
      <parent link="humerus_l"/>
      <child link="ulna_l"/>
      <axis xyz="0 0 1"/>
      <limit effort="100" lower="0" upper="3.0"/>
   </joint>
   <joint name="radioulnar_l" type="fixed">
      <origin rpy="0. -1.57 0." xyz="-0.006727 -0.013007 -0.026083"/>
      <parent link="ulna_l"/>
      <child link="radius_l"/>
   </joint>
   <joint name="radius_hand_l" type="fixed">
      <origin rpy="0. 0. 0." xyz="-0.008797 -0.235841 -0.013610"/>
      <parent link="radius_l"/>
      <child link="hand_l"/>
   </joint>
   <joint name="hip_r" type="spherical">
      <origin rpy="0. 0. 0." xyz="-0.056723 -0.079113 0.077873"/>
      <parent link="pelvis"/>
      <child link="femur_r"/>
      <axis xyz="0 0 1"/>
      <limit effort="400.0" lower="2.0"/>
   </joint>
   <joint name="walker_knee_r" type="revolute">
      <origin rpy="0. 0. 0." xyz="-0.000000 -0.375607 -0.001175"/>
      <parent link="femur_r"/>
      <child link="tibia_r"/>
      <axis xyz="0 0 1"/>
      <limit effort="200" lower="-2.2" upper="0"/>
   </joint>
   <joint name="patellofemoral_r" type="fixed">
      <origin rpy="0. 0. 0." xyz="-0.007514 -0.378890 -0.002554"/>
      <parent link="femur_r"/>
      <child link="patella_r"/>
   </joint>
   <joint name="ankle_r" type="revolute">
      <origin rpy="0. 0. 0." xyz="-0.010781 -0.431238 0.000000"/>
      <parent link="tibia_r"/>
      <child link="talus_r"/>
      <axis xyz="0 0 1"/>
      <limit effort="200.0" lower="-0.6981" upper="0.5236"/>
   </joint>
   <joint name="subtalar_r" type="revolute">
      <origin rpy="0. 0. 0." xyz="-0.052579 -0.045226 0.008539"/>
      <parent link="talus_r"/>
      <child link="calcn_r"/>
      <axis xyz="0.78717961000000003 0.60474746000000001 -0.12094949000000001"/>
      <limit effort="200.0" lower="-0.3491" upper="0.3491"/>
   </joint>
   <joint name="mtp_r" type="revolute">
      <origin rpy="0. 0. 0." xyz="0.158933 -0.001778 0.000960"/>
      <parent link="calcn_r"/>
      <child link="toes_r"/>
      <axis xyz="-0.58095439999999998 0 0.81393610999999999"/>
      <limit effort="200.0" lower="-0.5236" upper="0.5236"/>
   </joint>
   <joint name="hip_l" type="spherical">
      <origin rpy="0. 0. 0." xyz="-0.056723 -0.079113 -0.077873"/>
      <parent link="pelvis"/>
      <child link="femur_l"/>
      <axis xyz="0 0 1"/>
      <limit effort="400.0" lower="2.0"/>
   </joint>
   <joint name="walker_knee_l" type="revolute">
      <origin rpy="0. 0. 0." xyz="-0.000000 -0.375607 0.001175"/>
      <parent link="femur_l"/>
      <child link="tibia_l"/>
      <axis xyz="0 0 1"/>
      <limit effort="200" lower="-2.2" upper="0"/>
   </joint>
   <joint name="patellofemoral_l" type="fixed">
      <origin rpy="0. 0. 0." xyz="-0.007514 -0.378890 0.002554"/>
      <parent link="femur_l"/>
      <child link="patella_l"/>
   </joint>
   <joint name="ankle_l" type="revolute">
      <origin rpy="0. 0. 0." xyz="-0.010781 -0.431238 0.000000"/>
      <parent link="tibia_l"/>
      <child link="talus_l"/>
      <axis xyz="0 0 1"/>
      <limit effort="200.0" lower="-0.6981" upper="0.5236"/>
   </joint>
   <joint name="subtalar_l" type="revolute">
      <origin rpy="0. 0. 0." xyz="-0.052579 -0.045226 -0.008539"/>
      <parent link="talus_l"/>
      <child link="calcn_l"/>
      <axis xyz="-0.78717961000000003 -0.60474746000000001 -0.12094949000000001"/>
      <limit effort="200.0" lower="-0.3491" upper="0.3491"/>
   </joint>
   <joint name="mtp_l" type="revolute">
      <origin rpy="0. 0. 0." xyz="0.158933 -0.001778 -0.000960"/>
      <parent link="calcn_l"/>
      <child link="toes_l"/>
      <axis xyz="0.58095439999999998 0 0.81393610999999999"/>
      <limit effort="200.0" lower="-0.5236" upper="0.5236"/>
   </joint>
</robot>