<?xml version="1.0" encoding="utf-8"?>
<robot name="osim_robot">
   <link name="pelvis">
      <inertial>
         <mass value="11.72431872784953"/>
         <origin rpy="0 0 0" xyz="0 0 0"/>
         <inertia ixx="0.10072" ixy="0" ixz="0" iyy="0.085337" iyz="0" izz="0.056728"/>
      </inertial>
      <visual name="visual1">
         <geometry>
            <mesh filename="Geometry/r_pelvis.stl"
                  scale="0.99204811858833086 0.99204811858833086 0.99204811858833086"/>
         </geometry>
         <origin rpy="0 0 0" xyz="0 0 0"/>
         <material name="white">
            <color rgba="1 1 1 1"/>
         </material>
      </visual>
      <visual name="visual2">
         <geometry>
            <mesh filename="Geometry/l_pelvis.stl"
                  scale="0.99204811858833086 0.99204811858833086 0.99204811858833086"/>
         </geometry>
         <origin rpy="0 0 0" xyz="0 0 0"/>
         <material name="white">
            <color rgba="1 1 1 1"/>
         </material>
      </visual>
      <visual name="visual3">
         <geometry>
            <mesh filename="Geometry/sacrum.stl"
                  scale="0.99204811858833086 0.99204811858833086 0.99204811858833086"/>
         </geometry>
         <origin rpy="0 0 0" xyz="0 0 0"/>
         <material name="white">
            <color rgba="1 1 1 1"/>
         </material>
      </visual>
   </link>
   <link name="femur_r">
      <inertial>
         <mass value="9.2597926649587858"/>
         <origin rpy="0 0 0" xyz="0 0 0"/>
         <inertia ixx="0.13761" ixy="0" ixz="0" iyy="0.036072" iyz="0" izz="0.14511"/>
      </inertial>
      <visual name="visual1">
         <geometry>
            <mesh filename="Geometry/r_femur.stl"
                  scale="1.0160294433241892 1.0160294433241892 1.0160294433241892"/>
         </geometry>
         <origin rpy="0 0 0" xyz="0 0 0"/>
         <material name="white">
            <color rgba="1 1 1 1"/>
         </material>
      </visual>
      <collision>
         <origin rpy="1.57 0 0" xyz="0.000000 -0.203206 0.020321"/>
         <geometry>
            <capsule length="0.330210" radius="0.015240"/>
         </geometry>
      </collision>
   </link>
   <link name="tibia_r">
      <inertial>
         <mass value="3.6909154864143785"/>
         <origin rpy="0 0 0" xyz="0 0 0"/>
         <inertia ixx="0.047344" ixy="0" ixz="0" iyy="0.0047907" iyz="0" izz="0.048001"/>
      </inertial>
      <visual name="visual1">
         <geometry>
            <mesh filename="Geometry/r_tibia.stl"
                  scale="0.97138126209543119 0.97138126209543119 0.97138126209543119"/>
         </geometry>
         <origin rpy="0 0 0" xyz="0 0 0"/>
         <material name="white">
            <color rgba="1 1 1 1"/>
         </material>
      </visual>
      <collision>
         <origin rpy="1.57 0 0" xyz="0.000000 -0.145707 0.019428"/>
         <geometry>
            <capsule length="0.267130" radius="0.014571"/>
         </geometry>
      </collision>
      <visual name="visual2">
         <geometry>
            <mesh filename="Geometry/r_fibula.stl"
                  scale="0.97138126209543119 0.97138126209543119 0.97138126209543119"/>
         </geometry>
         <origin rpy="0 0 0" xyz="0 0 0"/>
         <material name="white">
            <color rgba="1 1 1 1"/>
         </material>
      </visual>
      <collision>
         <origin rpy="1.57 0 0" xyz="0.000000 -0.145707 0.019428"/>
         <geometry>
            <capsule length="0.267130" radius="0.014571"/>
         </geometry>
      </collision>
   </link>
   <link name="patella_r">
      <inertial>
         <mass value="0.085814407263363299"/>
         <origin rpy="0 0 0" xyz="0 0 0"/>
         <inertia ixx="2.9495e-06" ixy="0" ixz="0" iyy="1.3473e-05" iyz="0" izz="1.3473e-05"/>
      </inertial>
   </link>
   <link name="talus_r">
      <inertial>
         <mass value="0.099552676639632603"/>
         <origin rpy="0 0 0" xyz="0 0 0"/>
         <inertia ixx="0.00093936" ixy="0" ixz="0" iyy="0.00093936" iyz="0" izz="0.00093936"/>
      </inertial>
      <visual name="visual1">
         <geometry>
            <mesh filename="Geometry/r_talus.stl"
                  scale="0.97138126209543119 0.97138126209543119 0.97138126209543119"/>
         </geometry>
         <origin rpy="0 0 0" xyz="0 0 0"/>
         <material name="white">
            <color rgba="1 1 1 1"/>
         </material>
      </visual>
   </link>
   <link name="calcn_r">
      <inertial>
         <mass value="1.2444084579954076"/>
         <origin rpy="0 0 0" xyz="0 0 0"/>
         <inertia ixx="0.0011649" ixy="0" ixz="0" iyy="0.0032452" iyz="0" izz="0.0034116"/>
      </inertial>
      <visual name="visual1">
         <geometry>
            <mesh filename="Geometry/r_foot.stl"
                  scale="0.91423791712885905 0.91423791712885905 0.91423791712885905"/>
         </geometry>
         <origin rpy="0 0 0" xyz="0 0 0"/>
         <material name="white">
            <color rgba="1 1 1 1"/>
         </material>
      </visual>
      <collision>
         <origin rpy="0 0 0" xyz="0.027427 0.018285 0.000000"/>
         <geometry>
            <sphere radius="0.045712"/>
         </geometry>
      </collision>
   </link>
   <link name="toes_r">
      <inertial>
         <mass value="0.21563109760144419"/>
         <origin rpy="0 0 0" xyz="0 0 0"/>
         <inertia ixx="8.3209e-05" ixy="0" ixz="0" iyy="0.00016642" iyz="0" izz="0.00083209"/>
      </inertial>
      <visual name="visual1">
         <geometry>
            <mesh filename="Geometry/r_bofoot.stl"
                  scale="0.91423791712885905 0.91423791712885905 0.91423791712885905"/>
         </geometry>
         <origin rpy="0 0 0" xyz="0 0 0"/>
         <material name="white">
            <color rgba="1 1 1 1"/>
         </material>
      </visual>
      <collision>
         <origin rpy="0 0 0" xyz="0.018285 -0.004571 -0.023770"/>
         <geometry>
            <sphere radius="0.022856"/>
         </geometry>
      </collision>
      <collision>
         <origin rpy="0 0 0" xyz="0.018285 -0.004571 0.023770"/>
         <geometry>
            <sphere radius="0.022856"/>
         </geometry>
      </collision>
   </link>
   <link name="femur_l">
      <inertial>
         <mass value="9.2597926649587858"/>
         <origin rpy="0 0 0" xyz="0 0 0"/>
         <inertia ixx="0.13761" ixy="0" ixz="0" iyy="0.036072" iyz="0" izz="0.14511"/>
      </inertial>
      <visual name="visual1">
         <geometry>
            <mesh filename="Geometry/l_femur.stl"
                  scale="1.0160294433241892 1.0160294433241892 1.0160294433241892"/>
         </geometry>
         <origin rpy="0 0 0" xyz="0 0 0"/>
         <material name="white">
            <color rgba="1 1 1 1"/>
         </material>
      </visual>
      <collision>
         <origin rpy="1.57 0 0" xyz="0.000000 -0.203206 -0.020321"/>
         <geometry>
            <capsule length="0.330210" radius="0.015240"/>
         </geometry>
      </collision>
   </link>
   <link name="tibia_l">
      <inertial>
         <mass value="3.6909154864143785"/>
         <origin rpy="0 0 0" xyz="0 0 0"/>
         <inertia ixx="0.047344" ixy="0" ixz="0" iyy="0.0047907" iyz="0" izz="0.048001"/>
      </inertial>
      <visual name="visual1">
         <geometry>
            <mesh filename="Geometry/l_tibia.stl"
                  scale="0.97138126209543119 0.97138126209543119 0.97138126209543119"/>
         </geometry>
         <origin rpy="0 0 0" xyz="0 0 0"/>
         <material name="white">
            <color rgba="1 1 1 1"/>
         </material>
      </visual>
      <collision>
         <origin rpy="1.57 0 0" xyz="0.000000 -0.145707 -0.019428"/>
         <geometry>
            <capsule length="0.267130" radius="0.014571"/>
         </geometry>
      </collision>
      <visual name="visual2">
         <geometry>
            <mesh filename="Geometry/l_fibula.stl"
                  scale="0.97138126209543119 0.97138126209543119 0.97138126209543119"/>
         </geometry>
         <origin rpy="0 0 0" xyz="0 0 0"/>
         <material name="white">
            <color rgba="1 1 1 1"/>
         </material>
      </visual>
      <collision>
         <origin rpy="1.57 0 0" xyz="0.000000 -0.145707 -0.019428"/>
         <geometry>
            <capsule length="0.267130" radius="0.014571"/>
         </geometry>
      </collision>
   </link>
   <link name="patella_l">
      <inertial>
         <mass value="0.085814407263363299"/>
         <origin rpy="0 0 0" xyz="0 0 0"/>
         <inertia ixx="2.9495e-06" ixy="0" ixz="0" iyy="1.3473e-05" iyz="0" izz="1.3473e-05"/>
      </inertial>
   </link>
   <link name="talus_l">
      <inertial>
         <mass value="0.099552676639632603"/>
         <origin rpy="0 0 0" xyz="0 0 0"/>
         <inertia ixx="0.00093936" ixy="0" ixz="0" iyy="0.00093936" iyz="0" izz="0.00093936"/>
      </inertial>
      <visual name="visual1">
         <geometry>
            <mesh filename="Geometry/l_talus.stl"
                  scale="0.97138126209543119 0.97138126209543119 0.97138126209543119"/>
         </geometry>
         <origin rpy="0 0 0" xyz="0 0 0"/>
         <material name="white">
            <color rgba="1 1 1 1"/>
         </material>
      </visual>
   </link>
   <link name="calcn_l">
      <inertial>
         <mass value="1.2444084579954076"/>
         <origin rpy="0 0 0" xyz="0 0 0"/>
         <inertia ixx="0.0011649" ixy="0" ixz="0" iyy="0.0032452" iyz="0" izz="0.0034116"/>
      </inertial>
      <visual name="visual1">
         <geometry>
            <mesh filename="Geometry/l_foot.stl"
                  scale="0.91423791712885905 0.91423791712885905 0.91423791712885905"/>
         </geometry>
         <origin rpy="0 0 0" xyz="0 0 0"/>
         <material name="white">
            <color rgba="1 1 1 1"/>
         </material>
      </visual>
      <collision>
         <origin rpy="0 0 0" xyz="0.027427 0.018285 0.000000"/>
         <geometry>
            <sphere radius="0.045712"/>
         </geometry>
      </collision>
   </link>
   <link name="toes_l">
      <inertial>
         <mass value="0.21563109760144419"/>
         <origin rpy="0 0 0" xyz="0 0 0"/>
         <inertia ixx="8.3209e-05" ixy="0" ixz="0" iyy="0.00016642" iyz="0" izz="0.00083209"/>
      </inertial>
      <visual name="visual1">
         <geometry>
            <mesh filename="Geometry/l_bofoot.stl"
                  scale="0.91423791712885905 0.91423791712885905 0.91423791712885905"/>
         </geometry>
         <origin rpy="0 0 0" xyz="0 0 0"/>
         <material name="white">
            <color rgba="1 1 1 1"/>
         </material>
      </visual>
      <collision>
         <origin rpy="0 0 0" xyz="0.018285 -0.004571 -0.023770"/>
         <geometry>
            <sphere radius="0.022856"/>
         </geometry>
      </collision>
      <collision>
         <origin rpy="0 0 0" xyz="0.018285 -0.004571 0.023770"/>
         <geometry>
            <sphere radius="0.022856"/>
         </geometry>
      </collision>
   </link>
   <link name="torso">
      <inertial>
         <mass value="26.706598351407678"/>
         <origin rpy="0 0 0" xyz="0 0 0"/>
         <inertia ixx="1.7763" ixy="0" ixz="0" iyy="0.91014" iyz="0" izz="1.7244"/>
      </inertial>
      <visual name="visual1">
         <geometry>
            <mesh filename="Geometry/hat_spine.stl"
                  scale="1.1000435346346504 1.1000435346346504 1.1000435346346504"/>
         </geometry>
         <origin rpy="0 0 0" xyz="0 0 0"/>
         <material name="white">
            <color rgba="1 1 1 1"/>
         </material>
      </visual>
      <visual name="visual2">
         <geometry>
            <mesh filename="Geometry/hat_jaw.stl"
                  scale="1.1000435346346504 1.1000435346346504 1.1000435346346504"/>
         </geometry>
         <origin rpy="0 0 0" xyz="0 0 0"/>
         <material name="white">
            <color rgba="1 1 1 1"/>
         </material>
      </visual>
      <visual name="visual3">
         <geometry>
            <mesh filename="Geometry/hat_skull.stl"
                  scale="1.1000435346346504 1.1000435346346504 1.1000435346346504"/>
         </geometry>
         <origin rpy="0 0 0" xyz="0 0 0"/>
         <material name="white">
            <color rgba="1 1 1 1"/>
         </material>
      </visual>
      <visual name="visual4">
         <geometry>
            <mesh filename="Geometry/hat_ribs_scap.stl"
                  scale="1.1000435346346504 1.1000435346346504 1.1000435346346504"/>
         </geometry>
         <origin rpy="0 0 0" xyz="0 0 0"/>
         <material name="white">
            <color rgba="1 1 1 1"/>
         </material>
      </visual>
   </link>
   <link name="humerus_r">
      <inertial>
         <mass value="2.0234081527005325"/>
         <origin rpy="0 0 0" xyz="0 0 0"/>
         <inertia ixx="0.011893" ixy="0" ixz="0" iyy="0.0041026" iyz="0" izz="0.013349"/>
      </inertial>
      <visual name="visual1">
         <geometry>
            <mesh filename="Geometry/humerus_rv.stl" scale="1 1 1"/>
         </geometry>
         <origin rpy="0 0 0" xyz="0 0 0"/>
         <material name="white">
            <color rgba="1 1 1 1"/>
         </material>
      </visual>
   </link>
   <link name="ulna_r">
      <inertial>
         <mass value="0.60478251058576804"/>
         <origin rpy="0 0 0" xyz="0 0 0"/>
         <inertia ixx="0.0029488" ixy="0" ixz="0" iyy="0.00061524" iyz="0" izz="0.0031986"/>
      </inertial>
      <visual name="visual1">
         <geometry>
            <mesh filename="Geometry/ulna_rv.stl" scale="1 1 1"/>
         </geometry>
         <origin rpy="0 0 0" xyz="0 0 0"/>
         <material name="white">
            <color rgba="1 1 1 1"/>
         </material>
      </visual>
   </link>
   <link name="radius_r">
      <inertial>
         <mass value="0.60478251058576804"/>
         <origin rpy="0 0 0" xyz="0 0 0"/>
         <inertia ixx="0.0029488" ixy="0" ixz="0" iyy="0.00061524" iyz="0" izz="0.0031986"/>
      </inertial>
      <visual name="visual1">
         <geometry>
            <mesh filename="Geometry/radius_rv.stl" scale="1 1 1"/>
         </geometry>
         <origin rpy="0 0 0" xyz="0 0 0"/>
         <material name="white">
            <color rgba="1 1 1 1"/>
         </material>
      </visual>
   </link>
   <link name="hand_r">
      <inertial>
         <mass value="0.45545349562631915"/>
         <origin rpy="0 0 0" xyz="0 0 0"/>
         <inertia ixx="0.00088801" ixy="0" ixz="0" iyy="0.00054455" iyz="0" izz="0.001334"/>
      </inertial>
      <visual name="visual1">
         <geometry>
            <mesh filename="Geometry/pisiform_rvs.stl"
                  scale="0.84999999999999998 0.84999999999999998 0.84999999999999998"/>
         </geometry>
         <origin rpy="0 0 0" xyz="0 0 0"/>
         <material name="white">
            <color rgba="1 1 1 1"/>
         </material>
      </visual>
      <visual name="visual2">
         <geometry>
            <mesh filename="Geometry/lunate_rvs.stl"
                  scale="0.84999999999999998 0.84999999999999998 0.84999999999999998"/>
         </geometry>
         <origin rpy="0 0 0" xyz="0 0 0"/>
         <material name="white">
            <color rgba="1 1 1 1"/>
         </material>
      </visual>
      <visual name="visual3">
         <geometry>
            <mesh filename="Geometry/scaphoid_rvs.stl"
                  scale="0.84999999999999998 0.84999999999999998 0.84999999999999998"/>
         </geometry>
         <origin rpy="0 0 0" xyz="0 0 0"/>
         <material name="white">
            <color rgba="1 1 1 1"/>
         </material>
      </visual>
      <visual name="visual4">
         <geometry>
            <mesh filename="Geometry/triquetrum_rvs.stl"
                  scale="0.84999999999999998 0.84999999999999998 0.84999999999999998"/>
         </geometry>
         <origin rpy="0 0 0" xyz="0 0 0"/>
         <material name="white">
            <color rgba="1 1 1 1"/>
         </material>
      </visual>
      <visual name="visual5">
         <geometry>
            <mesh filename="Geometry/hamate_rvs.stl"
                  scale="0.84999999999999998 0.84999999999999998 0.84999999999999998"/>
         </geometry>
         <origin rpy="0 0 0" xyz="0 0 0"/>
         <material name="white">
            <color rgba="1 1 1 1"/>
         </material>
      </visual>
      <visual name="visual6">
         <geometry>
            <mesh filename="Geometry/capitate_rvs.stl"
                  scale="0.84999999999999998 0.84999999999999998 0.84999999999999998"/>
         </geometry>
         <origin rpy="0 0 0" xyz="0 0 0"/>
         <material name="white">
            <color rgba="1 1 1 1"/>
         </material>
      </visual>
      <visual name="visual7">
         <geometry>
            <mesh filename="Geometry/trapezoid_rvs.stl"
                  scale="0.84999999999999998 0.84999999999999998 0.84999999999999998"/>
         </geometry>
         <origin rpy="0 0 0" xyz="0 0 0"/>
         <material name="white">
            <color rgba="1 1 1 1"/>
         </material>
      </visual>
      <visual name="visual8">
         <geometry>
            <mesh filename="Geometry/trapezium_rvs.stl"
                  scale="0.84999999999999998 0.84999999999999998 0.84999999999999998"/>
         </geometry>
         <origin rpy="0 0 0" xyz="0 0 0"/>
         <material name="white">
            <color rgba="1 1 1 1"/>
         </material>
      </visual>
      <visual name="visual9">
         <geometry>
            <mesh filename="Geometry/metacarpal2_rvs.stl"
                  scale="0.84999999999999998 0.84999999999999998 0.84999999999999998"/>
         </geometry>
         <origin rpy="0 0 0" xyz="0 0 0"/>
         <material name="white">
            <color rgba="1 1 1 1"/>
         </material>
      </visual>
      <visual name="visual10">
         <geometry>
            <mesh filename="Geometry/index_proximal_rvs.stl"
                  scale="0.84999999999999998 0.84999999999999998 0.84999999999999998"/>
         </geometry>
         <origin rpy="0 0 0" xyz="0 0 0"/>
         <material name="white">
            <color rgba="1 1 1 1"/>
         </material>
      </visual>
      <visual name="visual11">
         <geometry>
            <mesh filename="Geometry/index_medial_rvs.stl"
                  scale="0.84999999999999998 0.84999999999999998 0.84999999999999998"/>
         </geometry>
         <origin rpy="0 0 0" xyz="0 0 0"/>
         <material name="white">
            <color rgba="1 1 1 1"/>
         </material>
      </visual>
      <visual name="visual12">
         <geometry>
            <mesh filename="Geometry/index_distal_rvs.stl"
                  scale="0.84999999999999998 0.84999999999999998 0.84999999999999998"/>
         </geometry>
         <origin rpy="0 0 0" xyz="0 0 0"/>
         <material name="white">
            <color rgba="1 1 1 1"/>
         </material>
      </visual>
      <visual name="visual13">
         <geometry>
            <mesh filename="Geometry/metacarpal3_rvs.stl"
                  scale="0.84999999999999998 0.84999999999999998 0.84999999999999998"/>
         </geometry>
         <origin rpy="0 0 0" xyz="0 0 0"/>
         <material name="white">
            <color rgba="1 1 1 1"/>
         </material>
      </visual>
      <visual name="visual14">
         <geometry>
            <mesh filename="Geometry/middle_proximal_rvs.stl"
                  scale="0.84999999999999998 0.84999999999999998 0.84999999999999998"/>
         </geometry>
         <origin rpy="0 0 0" xyz="0 0 0"/>
         <material name="white">
            <color rgba="1 1 1 1"/>
         </material>
      </visual>
      <visual name="visual15">
         <geometry>
            <mesh filename="Geometry/middle_medial_rvs.stl"
                  scale="0.84999999999999998 0.84999999999999998 0.84999999999999998"/>
         </geometry>
         <origin rpy="0 0 0" xyz="0 0 0"/>
         <material name="white">
            <color rgba="1 1 1 1"/>
         </material>
      </visual>
      <visual name="visual16">
         <geometry>
            <mesh filename="Geometry/middle_distal_rvs.stl"
                  scale="0.84999999999999998 0.84999999999999998 0.84999999999999998"/>
         </geometry>
         <origin rpy="0 0 0" xyz="0 0 0"/>
         <material name="white">
            <color rgba="1 1 1 1"/>
         </material>
      </visual>
      <visual name="visual17">
         <geometry>
            <mesh filename="Geometry/metacarpal4_rvs.stl"
                  scale="0.84999999999999998 0.84999999999999998 0.84999999999999998"/>
         </geometry>
         <origin rpy="0 0 0" xyz="0 0 0"/>
         <material name="white">
            <color rgba="1 1 1 1"/>
         </material>
      </visual>
      <visual name="visual18">
         <geometry>
            <mesh filename="Geometry/ring_proximal_rvs.stl"
                  scale="0.84999999999999998 0.84999999999999998 0.84999999999999998"/>
         </geometry>
         <origin rpy="0 0 0" xyz="0 0 0"/>
         <material name="white">
            <color rgba="1 1 1 1"/>
         </material>
      </visual>
      <visual name="visual19">
         <geometry>
            <mesh filename="Geometry/ring_medial_rvs.stl"
                  scale="0.84999999999999998 0.84999999999999998 0.84999999999999998"/>
         </geometry>
         <origin rpy="0 0 0" xyz="0 0 0"/>
         <material name="white">
            <color rgba="1 1 1 1"/>
         </material>
      </visual>
      <visual name="visual20">
         <geometry>
            <mesh filename="Geometry/ring_distal_rvs.stl"
                  scale="0.84999999999999998 0.84999999999999998 0.84999999999999998"/>
         </geometry>
         <origin rpy="0 0 0" xyz="0 0 0"/>
         <material name="white">
            <color rgba="1 1 1 1"/>
         </material>
      </visual>
      <visual name="visual21">
         <geometry>
            <mesh filename="Geometry/metacarpal5_rvs.stl"
                  scale="0.84999999999999998 0.84999999999999998 0.84999999999999998"/>
         </geometry>
         <origin rpy="0 0 0" xyz="0 0 0"/>
         <material name="white">
            <color rgba="1 1 1 1"/>
         </material>
      </visual>
      <visual name="visual22">
         <geometry>
            <mesh filename="Geometry/little_proximal_rvs.stl"
                  scale="0.84999999999999998 0.84999999999999998 0.84999999999999998"/>
         </geometry>
         <origin rpy="0 0 0" xyz="0 0 0"/>
         <material name="white">
            <color rgba="1 1 1 1"/>
         </material>
      </visual>
      <visual name="visual23">
         <geometry>
            <mesh filename="Geometry/little_medial_rvs.stl"
                  scale="0.84999999999999998 0.84999999999999998 0.84999999999999998"/>
         </geometry>
         <origin rpy="0 0 0" xyz="0 0 0"/>
         <material name="white">
            <color rgba="1 1 1 1"/>
         </material>
      </visual>
      <visual name="visual24">
         <geometry>
            <mesh filename="Geometry/little_distal_rvs.stl"
                  scale="0.84999999999999998 0.84999999999999998 0.84999999999999998"/>
         </geometry>
         <origin rpy="0 0 0" xyz="0 0 0"/>
         <material name="white">
            <color rgba="1 1 1 1"/>
         </material>
      </visual>
      <visual name="visual25">
         <geometry>
            <mesh filename="Geometry/metacarpal1_rvs.stl"
                  scale="0.84999999999999998 0.84999999999999998 0.84999999999999998"/>
         </geometry>
         <origin rpy="0 0 0" xyz="0 0 0"/>
         <material name="white">
            <color rgba="1 1 1 1"/>
         </material>
      </visual>
      <visual name="visual26">
         <geometry>
            <mesh filename="Geometry/thumb_proximal_rvs.stl"
                  scale="0.84999999999999998 0.84999999999999998 0.84999999999999998"/>
         </geometry>
         <origin rpy="0 0 0" xyz="0 0 0"/>
         <material name="white">
            <color rgba="1 1 1 1"/>
         </material>
      </visual>
      <visual name="visual27">
         <geometry>
            <mesh filename="Geometry/thumb_distal_rvs.stl"
                  scale="0.84999999999999998 0.84999999999999998 0.84999999999999998"/>
         </geometry>
         <origin rpy="0 0 0" xyz="0 0 0"/>
         <material name="white">
            <color rgba="1 1 1 1"/>
         </material>
      </visual>
   </link>
   <link name="humerus_l">
      <inertial>
         <mass value="2.0234081527005325"/>
         <origin rpy="0 0 0" xyz="0 0 0"/>
         <inertia ixx="0.011893" ixy="0" ixz="0" iyy="0.0041026" iyz="0" izz="0.013349"/>
      </inertial>
      <visual name="visual1">
         <geometry>
            <mesh filename="Geometry/humerus_lv.stl" scale="1 1 1"/>
         </geometry>
         <origin rpy="0 0 0" xyz="0 0 0"/>
         <material name="white">
            <color rgba="1 1 1 1"/>
         </material>
      </visual>
   </link>
   <link name="ulna_l">
      <inertial>
         <mass value="0.60478251058576804"/>
         <origin rpy="0 0 0" xyz="0 0 0"/>
         <inertia ixx="0.0029488" ixy="0" ixz="0" iyy="0.00061524" iyz="0" izz="0.0031986"/>
      </inertial>
      <visual name="visual1">
         <geometry>
            <mesh filename="Geometry/ulna_lv.stl" scale="1 1 1"/>
         </geometry>
         <origin rpy="0 0 0" xyz="0 0 0"/>
         <material name="white">
            <color rgba="1 1 1 1"/>
         </material>
      </visual>
   </link>
   <link name="radius_l">
      <inertial>
         <mass value="0.60478251058576804"/>
         <origin rpy="0 0 0" xyz="0 0 0"/>
         <inertia ixx="0.0029488" ixy="0" ixz="0" iyy="0.00061524" iyz="0" izz="0.0031986"/>
      </inertial>
      <visual name="visual1">
         <geometry>
            <mesh filename="Geometry/radius_lv.stl" scale="1 1 1"/>
         </geometry>
         <origin rpy="0 0 0" xyz="0 0 0"/>
         <material name="white">
            <color rgba="1 1 1 1"/>
         </material>
      </visual>
   </link>
   <link name="hand_l">
      <inertial>
         <mass value="0.45545349562631915"/>
         <origin rpy="0 0 0" xyz="0 0 0"/>
         <inertia ixx="0.00088801" ixy="0" ixz="0" iyy="0.00054455" iyz="0" izz="0.001334"/>
      </inertial>
      <visual name="visual1">
         <geometry>
            <mesh filename="Geometry/pisiform_lvs.stl"
                  scale="0.84999999999999998 0.84999999999999998 0.84999999999999998"/>
         </geometry>
         <origin rpy="0 0 0" xyz="0 0 0"/>
         <material name="white">
            <color rgba="1 1 1 1"/>
         </material>
      </visual>
      <visual name="visual2">
         <geometry>
            <mesh filename="Geometry/lunate_lvs.stl"
                  scale="0.84999999999999998 0.84999999999999998 0.84999999999999998"/>
         </geometry>
         <origin rpy="0 0 0" xyz="0 0 0"/>
         <material name="white">
            <color rgba="1 1 1 1"/>
         </material>
      </visual>
      <visual name="visual3">
         <geometry>
            <mesh filename="Geometry/scaphoid_lvs.stl"
                  scale="0.84999999999999998 0.84999999999999998 0.84999999999999998"/>
         </geometry>
         <origin rpy="0 0 0" xyz="0 0 0"/>
         <material name="white">
            <color rgba="1 1 1 1"/>
         </material>
      </visual>
      <visual name="visual4">
         <geometry>
            <mesh filename="Geometry/triquetrum_lvs.stl"
                  scale="0.84999999999999998 0.84999999999999998 0.84999999999999998"/>
         </geometry>
         <origin rpy="0 0 0" xyz="0 0 0"/>
         <material name="white">
            <color rgba="1 1 1 1"/>
         </material>
      </visual>
      <visual name="visual5">
         <geometry>
            <mesh filename="Geometry/hamate_lvs.stl"
                  scale="0.84999999999999998 0.84999999999999998 0.84999999999999998"/>
         </geometry>
         <origin rpy="0 0 0" xyz="0 0 0"/>
         <material name="white">
            <color rgba="1 1 1 1"/>
         </material>
      </visual>
      <visual name="visual6">
         <geometry>
            <mesh filename="Geometry/capitate_lvs.stl"
                  scale="0.84999999999999998 0.84999999999999998 0.84999999999999998"/>
         </geometry>
         <origin rpy="0 0 0" xyz="0 0 0"/>
         <material name="white">
            <color rgba="1 1 1 1"/>
         </material>
      </visual>
      <visual name="visual7">
         <geometry>
            <mesh filename="Geometry/trapezoid_lvs.stl"
                  scale="0.84999999999999998 0.84999999999999998 0.84999999999999998"/>
         </geometry>
         <origin rpy="0 0 0" xyz="0 0 0"/>
         <material name="white">
            <color rgba="1 1 1 1"/>
         </material>
      </visual>
      <visual name="visual8">
         <geometry>
            <mesh filename="Geometry/trapezium_lvs.stl"
                  scale="0.84999999999999998 0.84999999999999998 0.84999999999999998"/>
         </geometry>
         <origin rpy="0 0 0" xyz="0 0 0"/>
         <material name="white">
            <color rgba="1 1 1 1"/>
         </material>
      </visual>
      <visual name="visual9">
         <geometry>
            <mesh filename="Geometry/metacarpal2_lvs.stl"
                  scale="0.84999999999999998 0.84999999999999998 0.84999999999999998"/>
         </geometry>
         <origin rpy="0 0 0" xyz="0 0 0"/>
         <material name="white">
            <color rgba="1 1 1 1"/>
         </material>
      </visual>
      <visual name="visual10">
         <geometry>
            <mesh filename="Geometry/index_proximal_lvs.stl"
                  scale="0.84999999999999998 0.84999999999999998 0.84999999999999998"/>
         </geometry>
         <origin rpy="0 0 0" xyz="0 0 0"/>
         <material name="white">
            <color rgba="1 1 1 1"/>
         </material>
      </visual>
      <visual name="visual11">
         <geometry>
            <mesh filename="Geometry/index_medial_lvs.stl"
                  scale="0.84999999999999998 0.84999999999999998 0.84999999999999998"/>
         </geometry>
         <origin rpy="0 0 0" xyz="0 0 0"/>
         <material name="white">
            <color rgba="1 1 1 1"/>
         </material>
      </visual>
      <visual name="visual12">
         <geometry>
            <mesh filename="Geometry/index_distal_lvs.stl"
                  scale="0.84999999999999998 0.84999999999999998 0.84999999999999998"/>
         </geometry>
         <origin rpy="0 0 0" xyz="0 0 0"/>
         <material name="white">
            <color rgba="1 1 1 1"/>
         </material>
      </visual>
      <visual name="visual13">
         <geometry>
            <mesh filename="Geometry/metacarpal3_lvs.stl"
                  scale="0.84999999999999998 0.84999999999999998 0.84999999999999998"/>
         </geometry>
         <origin rpy="0 0 0" xyz="0 0 0"/>
         <material name="white">
            <color rgba="1 1 1 1"/>
         </material>
      </visual>
      <visual name="visual14">
         <geometry>
            <mesh filename="Geometry/middle_proximal_lvs.stl"
                  scale="0.84999999999999998 0.84999999999999998 0.84999999999999998"/>
         </geometry>
         <origin rpy="0 0 0" xyz="0 0 0"/>
         <material name="white">
            <color rgba="1 1 1 1"/>
         </material>
      </visual>
      <visual name="visual15">
         <geometry>
            <mesh filename="Geometry/middle_medial_lvs.stl"
                  scale="0.84999999999999998 0.84999999999999998 0.84999999999999998"/>
         </geometry>
         <origin rpy="0 0 0" xyz="0 0 0"/>
         <material name="white">
            <color rgba="1 1 1 1"/>
         </material>
      </visual>
      <visual name="visual16">
         <geometry>
            <mesh filename="Geometry/middle_distal_lvs.stl"
                  scale="0.84999999999999998 0.84999999999999998 0.84999999999999998"/>
         </geometry>
         <origin rpy="0 0 0" xyz="0 0 0"/>
         <material name="white">
            <color rgba="1 1 1 1"/>
         </material>
      </visual>
      <visual name="visual17">
         <geometry>
            <mesh filename="Geometry/metacarpal4_lvs.stl"
                  scale="0.84999999999999998 0.84999999999999998 0.84999999999999998"/>
         </geometry>
         <origin rpy="0 0 0" xyz="0 0 0"/>
         <material name="white">
            <color rgba="1 1 1 1"/>
         </material>
      </visual>
      <visual name="visual18">
         <geometry>
            <mesh filename="Geometry/ring_proximal_lvs.stl"
                  scale="0.84999999999999998 0.84999999999999998 0.84999999999999998"/>
         </geometry>
         <origin rpy="0 0 0" xyz="0 0 0"/>
         <material name="white">
            <color rgba="1 1 1 1"/>
         </material>
      </visual>
      <visual name="visual19">
         <geometry>
            <mesh filename="Geometry/ring_medial_lvs.stl"
                  scale="0.84999999999999998 0.84999999999999998 0.84999999999999998"/>
         </geometry>
         <origin rpy="0 0 0" xyz="0 0 0"/>
         <material name="white">
            <color rgba="1 1 1 1"/>
         </material>
      </visual>
      <visual name="visual20">
         <geometry>
            <mesh filename="Geometry/ring_distal_lvs.stl"
                  scale="0.84999999999999998 0.84999999999999998 0.84999999999999998"/>
         </geometry>
         <origin rpy="0 0 0" xyz="0 0 0"/>
         <material name="white">
            <color rgba="1 1 1 1"/>
         </material>
      </visual>
      <visual name="visual21">
         <geometry>
            <mesh filename="Geometry/metacarpal5_lvs.stl"
                  scale="0.84999999999999998 0.84999999999999998 0.84999999999999998"/>
         </geometry>
         <origin rpy="0 0 0" xyz="0 0 0"/>
         <material name="white">
            <color rgba="1 1 1 1"/>
         </material>
      </visual>
      <visual name="visual22">
         <geometry>
            <mesh filename="Geometry/little_proximal_lvs.stl"
                  scale="0.84999999999999998 0.84999999999999998 0.84999999999999998"/>
         </geometry>
         <origin rpy="0 0 0" xyz="0 0 0"/>
         <material name="white">
            <color rgba="1 1 1 1"/>
         </material>
      </visual>
      <visual name="visual23">
         <geometry>
            <mesh filename="Geometry/little_medial_lvs.stl"
                  scale="0.84999999999999998 0.84999999999999998 0.84999999999999998"/>
         </geometry>
         <origin rpy="0 0 0" xyz="0 0 0"/>
         <material name="white">
            <color rgba="1 1 1 1"/>
         </material>
      </visual>
      <visual name="visual24">
         <geometry>
            <mesh filename="Geometry/little_distal_lvs.stl"
                  scale="0.84999999999999998 0.84999999999999998 0.84999999999999998"/>
         </geometry>
         <origin rpy="0 0 0" xyz="0 0 0"/>
         <material name="white">
            <color rgba="1 1 1 1"/>
         </material>
      </visual>
      <visual name="visual25">
         <geometry>
            <mesh filename="Geometry/metacarpal1_lvs.stl"
                  scale="0.84999999999999998 0.84999999999999998 0.84999999999999998"/>
         </geometry>
         <origin rpy="0 0 0" xyz="0 0 0"/>
         <material name="white">
            <color rgba="1 1 1 1"/>
         </material>
      </visual>
      <visual name="visual26">
         <geometry>
            <mesh filename="Geometry/thumb_proximal_lvs.stl"
                  scale="0.84999999999999998 0.84999999999999998 0.84999999999999998"/>
         </geometry>
         <origin rpy="0 0 0" xyz="0 0 0"/>
         <material name="white">
            <color rgba="1 1 1 1"/>
         </material>
      </visual>
      <visual name="visual27">
         <geometry>
            <mesh filename="Geometry/thumb_distal_lvs.stl"
                  scale="0.84999999999999998 0.84999999999999998 0.84999999999999998"/>
         </geometry>
         <origin rpy="0 0 0" xyz="0 0 0"/>
         <material name="white">
            <color rgba="1 1 1 1"/>
         </material>
      </visual>
   </link>
   <joint name="back" type="spherical">
      <origin rpy="0. 0. 0." xyz="-0.099899 0.080852 0.000000"/>
      <parent link="pelvis"/>
      <child link="torso"/>
      <axis xyz="0 0 1"/>
      <limit effort="400" lower="1.57"/>
   </joint>
   <joint name="acromial_r" type="spherical">
      <origin rpy="0. 0. 0." xyz="0.003471 0.408666 0.187007"/>
      <parent link="torso"/>
      <child link="humerus_r"/>
      <axis xyz="0 0 1"/>
      <limit effort="100" lower="1.57"/>
   </joint>
   <joint name="elbow_r" type="revolute">
      <origin rpy="0. 0. 0." xyz="0.013144 -0.286273 -0.009595"/>
      <parent link="humerus_r"/>
      <child link="ulna_r"/>
      <axis xyz="0 0 1"/>
      <limit effort="100" lower="0" upper="3.0"/>
   </joint>
   <joint name="radioulnar_r" type="fixed">
      <origin rpy="0. 1.57 0." xyz="-0.006727 -0.013007 0.026083"/>
      <parent link="ulna_r"/>
      <child link="radius_r"/>
   </joint>
   <joint name="radius_hand_r" type="fixed">
      <origin rpy="0. 0. 0." xyz="-0.008797 -0.235841 0.013610"/>
      <parent link="radius_r"/>
      <child link="hand_r"/>
   </joint>
   <joint name="acromial_l" type="spherical">
      <origin rpy="0. 0. 0." xyz="0.003471 0.408666 -0.187007"/>
      <parent link="torso"/>
      <child link="humerus_l"/>
      <axis xyz="0 0 1"/>
      <limit effort="100" lower="1.57"/>
   </joint>
   <joint name="elbow_l" type="revolute">
      <origin rpy="0. 0. 0." xyz="0.013144 -0.286273 0.009595"/>
      <parent link="humerus_l"/>
      <child link="ulna_l"/>
      <axis xyz="0 0 1"/>
      <limit effort="100" lower="0" upper="3.0"/>
   </joint>
   <joint name="radioulnar_l" type="fixed">
      <origin rpy="0. -1.57 0." xyz="-0.006727 -0.013007 -0.026083"/>
      <parent link="ulna_l"/>
      <child link="radius_l"/>
   </joint>
   <joint name="radius_hand_l" type="fixed">
      <origin rpy="0. 0. 0." xyz="-0.008797 -0.235841 -0.013610"/>
      <parent link="radius_l"/>
      <child link="hand_l"/>
   </joint>
   <joint name="hip_r" type="spherical">
      <origin rpy="0. 0. 0." xyz="-0.055828 -0.077866 0.076646"/>
      <parent link="pelvis"/>
      <child link="femur_r"/>
      <axis xyz="0 0 1"/>
      <limit effort="400.0" lower="2.0"/>
   </joint>
   <joint name="walker_knee_r" type="revolute">
      <origin rpy="0. 0. 0." xyz="-0.000000 -0.410908 -0.001286"/>
      <parent link="femur_r"/>
      <child link="tibia_r"/>
      <axis xyz="0 0 1"/>
      <limit effort="200" lower="-2.2" upper="0"/>
   </joint>
   <joint name="patellofemoral_r" type="fixed">
      <origin rpy="0. 0. 0." xyz="-0.008220 -0.414499 -0.002794"/>
      <parent link="femur_r"/>
      <child link="patella_r"/>
   </joint>
   <joint name="ankle_r" type="revolute">
      <origin rpy="0. 0. 0." xyz="-0.009714 -0.388553 0.000000"/>
      <parent link="tibia_r"/>
      <child link="talus_r"/>
      <axis xyz="0 0 1"/>
      <limit effort="200.0" lower="-0.6981" upper="0.5236"/>
   </joint>
   <joint name="subtalar_r" type="revolute">
      <origin rpy="0. 0. 0." xyz="-0.047374 -0.040749 0.007693"/>
      <parent link="talus_r"/>
      <child link="calcn_r"/>
      <axis xyz="0.78717961000000003 0.60474746000000001 -0.12094949000000001"/>
      <limit effort="200.0" lower="-0.3491" upper="0.3491"/>
   </joint>
   <joint name="mtp_r" type="revolute">
      <origin rpy="0. 0. 0." xyz="0.163466 -0.001828 0.000987"/>
      <parent link="calcn_r"/>
      <child link="toes_r"/>
      <axis xyz="-0.58095439999999998 0 0.81393610999999999"/>
      <limit effort="200.0" lower="-0.5236" upper="0.5236"/>
   </joint>
   <joint name="hip_l" type="spherical">
      <origin rpy="0. 0. 0." xyz="-0.055828 -0.077866 -0.076646"/>
      <parent link="pelvis"/>
      <child link="femur_l"/>
      <axis xyz="0 0 1"/>
      <limit effort="400.0" lower="2.0"/>
   </joint>
   <joint name="walker_knee_l" type="revolute">
      <origin rpy="0. 0. 0." xyz="-0.000000 -0.410908 0.001286"/>
      <parent link="femur_l"/>
      <child link="tibia_l"/>
      <axis xyz="0 0 1"/>
      <limit effort="200" lower="-2.2" upper="0"/>
   </joint>
   <joint name="patellofemoral_l" type="fixed">
      <origin rpy="0. 0. 0." xyz="-0.008220 -0.414499 0.002794"/>
      <parent link="femur_l"/>
      <child link="patella_l"/>
   </joint>
   <joint name="ankle_l" type="revolute">
      <origin rpy="0. 0. 0." xyz="-0.009714 -0.388553 0.000000"/>
      <parent link="tibia_l"/>
      <child link="talus_l"/>
      <axis xyz="0 0 1"/>
      <limit effort="200.0" lower="-0.6981" upper="0.5236"/>
   </joint>
   <joint name="subtalar_l" type="revolute">
      <origin rpy="0. 0. 0." xyz="-0.047374 -0.040749 -0.007693"/>
      <parent link="talus_l"/>
      <child link="calcn_l"/>
      <axis xyz="-0.78717961000000003 -0.60474746000000001 -0.12094949000000001"/>
      <limit effort="200.0" lower="-0.3491" upper="0.3491"/>
   </joint>
   <joint name="mtp_l" type="revolute">
      <origin rpy="0. 0. 0." xyz="0.163466 -0.001828 -0.000987"/>
      <parent link="calcn_l"/>
      <child link="toes_l"/>
      <axis xyz="0.58095439999999998 0 0.81393610999999999"/>
      <limit effort="200.0" lower="-0.5236" upper="0.5236"/>
   </joint>
</robot>