<?xml version="1.0" ?>
<!-- =================================================================================== -->
<!-- |    This document was autogenerated by xacro from /home/mayankm/rsl_vt/catkin_ws/src/kinova_common/kinova_description/urdf/kinova.urdf.xacro | -->
<!-- |    EDITING THIS FILE BY HAND IS NOT RECOMMENDED                                 | -->
<!-- =================================================================================== -->
<!-- j2s6_3 refers to jaco v2 6DOF spherical 3fingers -->
<robot name="treadmill_model">

  <link name="world">  </link>

  <joint name="world_to_base" type="fixed">
    <axis xyz="0 0 0"/>
    <origin xyz="0.0 0.0 -0.086"/>
    <parent link="world"/>
    <child link="base"/>
  </joint>

  <link name="base">
  </link>

  <!-- <link name="treadmill">
    <inertial>
      <mass value="30.5"/>
      <inertia ixx="1.6522" ixy="0.0" ixz="0.0" iyy="4066.6922" iyz="0.0" izz="4068.2934"/>
    </inertial>
    <visual>
      <geometry>
        <box size="40 0.8 0.1"/>
      </geometry>
      <origin xyz="17 1.2 0"/>
    </visual>
    <collision>
      <geometry>
        <box size="40 0.8 0.1"/>
      </geometry>
      <origin xyz="17 1.2 0"/>
    </collision>
  </link> -->

  <!-- <joint name="belt_joint" type="prismatic">
    <axis xyz="1 0 0"/>
    <origin xyz="0.0 0.0 0.0"/>
    <parent link="base"/>
    <child link="treadmill"/>
    <limit effort="1000.0" lower="-50" upper="50"/>
  </joint> -->

  <link name="treadmill_">
    <inertial>
      <mass value="30.5"/>
      <inertia ixx="1.6522" ixy="0.0" ixz="0.0" iyy="4066.6922" iyz="0.0" izz="4068.2934"/>
    </inertial>
    <!-- <visual>
      <geometry>
        <box size="40 0.8 0.1"/>
      </geometry>
      <origin xyz="17 1.2 0"/>
    </visual> -->
    <visual>
      <geometry>
        <mesh filename="treadmill_export.gltf"/>
      </geometry>
      <origin xyz="-3.36 1.60 1"/>
    </visual>
  </link>

  <joint name="base_treadmill" type="prismatic">
    <axis xyz="1 0 0"/>
    <origin xyz="0.0 0.0 0.0"/>
    <parent link="base"/>
    <child link="treadmill_"/>
  </joint>
</robot>



<!-- <?xml version="1.0"?>
<robot name="Treadmills">
  <link name="world">  </link>

  <joint name="world_to_base" type="fixed">
    <axis xyz="0 0 0"/>
    <origin xyz="0.0 0.0 -0.086"/>
    <parent link="world"/>
    <child link="base"/>
  </joint>

  <link name="base">
  </link>

  <link name="treadmill">
    <inertial>
      <mass value="30.5"/>
      <inertia ixx="1.6522" ixy="0.0" ixz="0.0" iyy="4066.6922" iyz="0.0" izz="4068.2934"/>
    </inertial>
    <visual>
      <geometry>
        <box size="40 0.8 0.1"/>
      </geometry>
      <origin xyz="17 1.2 0"/>
    </visual>
    <collision>
      <geometry>
        <box size="40 0.8 0.1"/>
      </geometry>
      <origin xyz="17 1.2 0"/>
    </collision>
  </link>

  <joint name="belt_joint" type="prismatic">
    <axis xyz="1 0 0"/>
    <origin xyz="0.0 0.0 0.0"/>
    <parent link="base"/>
    <child link="treadmill"/>
    <limit effort="1000.0" lower="-50" upper="50"/>
  </joint>

</robot> -->
