<?xml version="1.0"?>

<robot name="humanoid">

	<!-- Pelvis: Root  -->
	<link name="pelvis">
		<inertial>
			<origin rpy = "0 0 0" xyz = "0.000000 0.070000 0.000000" />
			<mass value = "12.000000" />
			<inertia ixx = "0.03888" ixy = "0" ixz = "0" iyy = "0.03888" iyz = "0" izz = "0.03888" />
		</inertial>
		<collision>
			<origin rpy = "0 0 0" xyz = "0.000000 0.070000 0.000000" />
			<geometry>
				<sphere radius = "0.090000" />
			</geometry>
		</collision>
		<visual>
			<origin rpy = "0 0 0" xyz = "0.000000 0.070000 0.000000" />
			<geometry>
				<sphere radius = "0.090000" />
			</geometry>
		</visual>
	</link>

	<!-- Torso  -->
	<link name="torso">
		<inertial>
			<origin rpy = "0 0 0" xyz = "0.000000 0.120000 0.000000" />
			<mass value = "28.000000" />
			<inertia ixx = "0.1552" ixy = "0" ixz = "0" iyy = "0.1552" iyz = "0" izz = "0.1552" />
		</inertial>
		<collision>
			<origin rpy = "0 0 0" xyz = "0.000000 0.120000 0.000000" />
			<geometry>
				<sphere radius = "0.110000" />
			</geometry>
		</collision>
		<visual>
			<origin rpy = "0 0 0" xyz = "0.000000 0.120000 0.000000" />
			<geometry>
				<sphere radius = "0.110000" />
			</geometry>
		</visual>
	</link>

	<joint name="lumbar" type="spherical">
		<parent link="pelvis" />
		<child link="torso" />
		<origin rpy = "0 0 0" xyz = "0.000000 0.234 0.000000" />
		<limit lower = "3" />
	</joint>

	<!-- Head -->
	<link name="head">
		<inertial>
			<origin rpy = "0 0 0" xyz = "0.000000 0.17500000 0.000000" />
			<mass value = "4.000000" />
			<inertia ixx = "0.0174" ixy = "0" ixz = "0" iyy = "0.0174" iyz = "0" izz = "0.0174" />
		</inertial>
		<collision>
			<origin rpy = "0 0 0" xyz = "0.000000 0.1750000 0.000000" />
			<geometry>
				<sphere radius = "0.1050000" />
			</geometry>
		</collision>
		<visual>
			<origin rpy = "0 0 0" xyz = "0.000000 0.17500000 0.000000" />
			<geometry>
				<sphere radius = "0.1050000" />
			</geometry>
		</visual>
	</link>

	<joint name="neck" type="spherical">
		<parent link="torso" />
		<child link="head" />
		<origin rpy = "0 0 0" xyz = "0.000000 0.224 0.000000" />
		<limit lower = "3.0" />
	</joint>

	<!-- Right Thigh -->
	<link name="right_thigh">
		<inertial>
			<origin rpy = "-1.570796 0 0" xyz = "0.000000 -0.240000 0" />
			<mass value = "9.00000" />
			<inertia ixx = "0.126" ixy = "0" ixz = "0" iyy = "0.126" iyz = "0" izz = "0.0138" />
		</inertial>
		<collision>
			<origin rpy = "-1.570796 0 0" xyz = "0.000000 -0.240000 0.000000" />
			<geometry>
				<capsule length="0.1200000" radius="0.055000"/>
			</geometry>
		</collision>
		<visual>
			<origin rpy = "-1.570796 0 0" xyz = "0.000000 -0.240000 0.000000" />
			<geometry>
				<capsule length="0.1200000" radius="0.0550000"/>
			</geometry>
		</visual>
	</link>

	<joint name="right_hip" type="spherical">
		<parent link="pelvis" />
		<child link="right_thigh" />
		<origin rpy="0 0 0" xyz="0 0 0.085" />
		<limit lower = "4.0" />
	</joint>

	<!-- Right Shank -->
	<link name="right_shank">
		<inertial>
			<origin rpy = "-1.570796 0 0" xyz = "0.000000 -0.210000 0.000000" />
			<mass value = "6.000000" />
			<inertia ixx = "0.0754" ixy = "0" ixz = "0" iyy = "0.0754" iyz = "0" izz = "0.007234" />
		</inertial>
		<collision>
			<origin rpy = "-1.570796 0 0" xyz = "0.000000 -0.210000 0.000000" />
			<geometry>
				<capsule length="0.120000" radius="0.0500000"/>
			</geometry>
		</collision>
		<visual>
			<origin rpy = "-1.570796 0 0" xyz = "0.000000 -0.210000 0.000000" />
			<geometry>
				<capsule length="0.12000" radius="0.0500000"/>
			</geometry>
		</visual>
	</link>

	<joint name="right_knee" type="revolute">
		<parent link="right_thigh" />
		<child link="right_shank" />
		<origin rpy="0 0 0" xyz="0.000000 -0.42 0.000000" />
		<axis xyz="0.000000 0.000000 1.000000" />
		<limit lower="-2.2" upper="0" />
		<!-- <limit effort="1000.0" lower="-3.14" upper="3.14" velocity="1.5"/> -->
	</joint>

	<!-- Right Foot -->
	<link name="right_foot">
		<inertial>
			<origin rpy = "0 0 0" xyz = "0.0450000 -0.02250000 0.000000" />
			<mass value = "2.000000" />
			<inertia ixx = "0.0018542" ixy = "0" ixz = "0" iyy = "0.006572" iyz = "0" izz = "0.00573" />
		</inertial>
		<collision>
			<origin rpy = "0 0 0" xyz = "0.0450000 -0.02250000 0.000000" />
			<geometry>
				<box size="0.177000 0.0550000 0.090000" />
			</geometry>
		</collision>
		<visual>
			<origin rpy = "0 0 0" xyz = "0.0450000 -0.02250000 0.000000" />
			<geometry>
				<box size="0.177000 0.0550000 0.090000" />
			</geometry>
		</visual>
	</link>

	<joint name="right_ankle" type="spherical">
		<parent link="right_shank" />
		<child link="right_foot" />
		<origin rpy="0 0 0" xyz="0.000000 -0.4098 0.000000" />
		<limit lower="3" />
	</joint>

	<!-- Right Upper Arm -->
	<link name="right_upperarm">
		<inertial>
			<origin rpy = "-1.570796 0 0" xyz = "0.0000000 -0.14 0" />
			<mass value = "3.00000" />
			<inertia ixx = "0.0162" ixy = "0" ixz = "0" iyy = "0.0162" iyz = "0" izz = "0.002886" />
		</inertial>
		<collision>
			<origin rpy = "-1.570796 0 0" xyz = "0.000000 -0.140000 0.000000" />
			<geometry>
				<capsule length="0.090000" radius="0.0450000"/>
			</geometry>
		</collision>
		<visual>
			<origin rpy = "-1.570796 0 0" xyz = "0.000000 -0.140000 0.000000" />
			<geometry>
				<capsule length="0.090000" radius="0.0450000"/>
			</geometry>
		</visual>
	</link>

	<joint name="right_shoulder" type="spherical">
		<parent link="torso" />
		<child link="right_upperarm" />
		<origin rpy = "0 0 0" xyz = "-0.024 0.243 0.183" />
		<limit lower="3.0" />
	</joint>

	<!-- Right Lower Arm -->
	<link name="right_lowerarm">
		<inertial>
			<origin rpy = "-1.570796 0 0" xyz = "0.000000 -0.120000 0.000000" />
			<mass value = "2.000000" />
			<inertia ixx = "0.006904" ixy = "0" ixz = "0" iyy = "0.006904" iyz = "0" izz = "0.00159" />
		</inertial>
		<collision>
			<origin rpy = "-1.570796 0 0" xyz = "0.000000 -0.120000 0.000000" />
			<geometry>
				<capsule length="0.0680000" radius="0.040000"/>
			</geometry>
		</collision>
		<visual>
			<origin rpy = "-1.570796 0 0" xyz = "0.000000 -0.120000 0.000000" />
			<geometry>
				<capsule length="0.0680000" radius="0.040000"/>
			</geometry>
		</visual>
	</link>

	<joint name="right_elbow" type="revolute">
		<parent link="right_upperarm" />
		<child link="right_lowerarm" />
		<origin rpy = "0 0 0" xyz = "0 -0.275 0 " />
		<axis xyz = "0.000000 0.000000 1.000000" />
		<limit lower="0" upper="3.0" />
		<!-- <limit effort="1000.0" lower="-3.14" upper="3.14" velocity="1.5"/> -->
	</joint>

	<!-- Right Hand -->
	<link name="right_hand">
		<inertial>
			<origin rpy = "0 0 0" xyz = "0.000000 0.000000 0.000000" />
			<mass value = "1.00000" />
			<inertia ixx = "0.00064" ixy = "0" ixz = "0" iyy = "0.00064" iyz = "0" izz = "0.00064" />
		</inertial>
		<collision>
			<origin rpy = "0 0 0" xyz = "0.000000 0.000000 0.000000" />
			<geometry>
				<sphere radius = "0.040000" />
			</geometry>
		</collision>
		<visual>
			<origin rpy = "0 0 0" xyz = "0.000000 0.000000 0.000000" />
			<geometry>
				<sphere radius = "0.040000" />
			</geometry>
		</visual>
	</link>

	<joint name="right_wrist" type="fixed">
		<parent link="right_lowerarm" />
		<child link="right_hand" />
		<origin rpy = "0 0 0" xyz = "0.000000 -0.26 0.000000" />
	</joint>

	<!-- Left Thigh -->
	<link name="left_thigh">
		<inertial>
			<origin rpy = "-1.570796 0 0" xyz = "0.000000 -0.240000 0.000000" />
			<mass value = "9.00000" />
			<inertia ixx = "0.126" ixy = "0" ixz = "0" iyy = "0.126" iyz = "0" izz = "0.0138" />
		</inertial>
		<collision>
			<origin rpy = "-1.570796 0 0" xyz = "0.000000 -0.240000 0.000000" />
			<geometry>
				<capsule length="0.1200000" radius="0.0550000"/>
			</geometry>
		</collision>
		<visual>
			<origin rpy = "-1.570796 0 0" xyz = "0.000000 -0.240000 0.000000" />
			<geometry>
				<capsule length="0.120000" radius="0.0550000"/>
			</geometry>
		</visual>
	</link>

	<joint name="left_hip" type="spherical">
		<parent link="pelvis" />
		<child link="left_thigh" />
		<origin rpy = "0 0 0" xyz = "0.000000 0.0000 -0.085" />
		<limit lower = "4.0" />
		<!-- <dynamics damping="0.0" friction="0.0" /> -->
	</joint>

	<!-- Left Shank -->
	<link name="left_shank">
		<inertial>
			<origin rpy = "-1.570796 0 0" xyz = "0.000000 -0.210000 0.000000" />
			<mass value = "6.000000" />
			<inertia ixx = "0.0754" ixy = "0" ixz = "0" iyy = "0.0754" iyz = "0" izz = "0.007234" />
		</inertial>
		<collision>
			<origin rpy = "-1.570796 0 0" xyz = "0.000000 -0.210000 0.000000" />
			<geometry>
				<capsule length="0.120000" radius="0.0500000"/>
			</geometry>
		</collision>
		<visual>
			<origin rpy = "-1.570796 0 0" xyz = "0.000000 -0.210000 0.000000" />
			<geometry>
				<capsule length="0.1200000" radius="0.0500000"/>
			</geometry>
		</visual>
	</link>

	<joint name="left_knee" type="revolute">
		<parent link="left_thigh" />
		<child link="left_shank" />
		<origin rpy="0 0 0" xyz="0.000000 -0.42 0.000000" />
		<axis xyz="0.000000 0.000000 1.000000" />
		<limit lower="-2.2" upper="0" />
		<!-- <limit effort="1000.0" lower="-3.14" upper="3.14" velocity="1.5"/> -->
	</joint>

	<!-- Left Foot -->
	<link name="left_foot">
		<inertial>
			<origin rpy = "0 0 0" xyz = "0.0450000 -0.02250000 0.000000" />
			<mass value = "2.000000" />
			<inertia ixx = "0.0018542" ixy = "0" ixz = "0" iyy = "0.006572" iyz = "0" izz = "0.00573" />
		</inertial>
		<collision>
			<origin rpy = "0 0 0" xyz = "0.0450000 -0.02250000 0.000000" />
			<geometry>
				<box size="0.177000 0.0550000 0.090000" />
			</geometry>
		</collision>
		<visual>
			<origin rpy = "0 0 0" xyz = "0.0450000 -0.02250000 0.000000" />
			<geometry>
				<box size="0.177000 0.0550000 0.090000" />
			</geometry>
		</visual>
	</link>

	<joint name="left_ankle" type="spherical">
		<parent link="left_shank" />
		<child link="left_foot" />
		<origin rpy = "0 0 0" xyz = "0.000000 -0.4098 0.000000" />
		<limit lower="3" />
		<!-- <dynamics damping="0.0" friction="0.0" /> -->
	</joint>

	<!-- Left Upper Arm -->
	<link name="left_upperarm">
		<inertial>
			<origin rpy = "-1.570796 0 0" xyz = "0.000000 -0.14 0" />
			<mass value = "3.00000" />
			<inertia ixx = "0.0162" ixy = "0" ixz = "0" iyy = "0.0162" iyz = "0" izz = "0.002886" />
		</inertial>
		<collision>
			<origin rpy = "-1.570796 0 0" xyz = "0.000000 -0.140000 0.000000" />
			<geometry>
				<capsule length="0.090000" radius="0.0450000"/>
			</geometry>
		</collision>
		<visual>
			<origin rpy = "-1.570796 0 0" xyz = "0.000000 -0.140000 0.000000" />
			<geometry>
				<capsule length="0.090000" radius="0.0450000"/>
			</geometry>
		</visual>
	</link>

	<joint name="left_shoulder" type="spherical">
		<parent link="torso" />
		<child link="left_upperarm" />
		<origin rpy = "0 0 0" xyz = "-0.024 0.243 -0.183" />
		<limit lower="3.0" />
	</joint>

	<!-- Left Lower Arm -->
	<link name="left_lowerarm">
		<inertial>
			<origin rpy = "-1.570796 0 0" xyz = "0.000000 -0.120000 0.000000" />
			<mass value = "2.000000" />
			<inertia ixx = "0.006904" ixy = "0" ixz = "0" iyy = "0.006904" iyz = "0" izz = "0.00159" />
		</inertial>
		<collision>
			<origin rpy = "-1.570796 0 0" xyz = "0.000000 -0.120000 0.000000" />
			<geometry>
				<capsule length="0.0680000" radius="0.040000"/>
			</geometry>
		</collision>
		<visual>
			<origin rpy = "-1.570796 0 0" xyz = "0.000000 -0.120000 0.000000" />
			<geometry>
				<capsule length="0.0680000" radius="0.040000"/>
			</geometry>
		</visual>
	</link>

	<joint name="left_elbow" type="revolute">
		<parent link="left_upperarm" />
		<child link="left_lowerarm" />
		<origin rpy = "0 0 0" xyz = "0.000000 -0.275 0.000000" />
		<axis xyz = "0.000000 0.000000 1.000000" />
		<limit lower="0" upper="3.0" />
		<!-- <dynamics damping="0.0" friction="0.0" /> -->
		<!-- <limit effort="1000.0" lower="-3.14" upper="3.14" velocity="1.5"/> -->
	</joint>

	<!-- Left Hand -->
	<link name="left_hand">
		<inertial>
			<origin rpy = "0 0 0" xyz = "0.000000 0.000000 0.000000" />
			<mass value = "1.00000" />
			<inertia ixx = "0.00064" ixy = "0" ixz = "0" iyy = "0.00064" iyz = "0" izz = "0.00064" />
		</inertial>
		<collision>
			<origin rpy = "0 0 0" xyz = "0.000000 0.000000 0.000000" />
			<geometry>
				<sphere radius = "0.040000" />
			</geometry>
		</collision>
		<visual>
			<origin rpy = "0 0 0" xyz = "0.000000 0.000000 0.000000" />
			<geometry>
				<sphere radius = "0.040000" />
			</geometry>
		</visual>
	</link>

	<joint name="left_wrist" type="fixed">
		<parent link="left_lowerarm" />
		<child link="left_hand" />
		<origin rpy = "0 0 0" xyz = "0.000000 -0.26 0.000000" />
	</joint>
</robot>
