<?xml version="1.0" encoding="utf-8"?>
<robot name="osim_robot">
   <link name="pelvis">
      <inertial>
         <mass value="11.25534597873555"/>
         <origin rpy="0 0 0" xyz="0 0 0"/>
         <inertia ixx="0.10699" ixy="0" ixz="0" iyy="0.090652" iyz="0" izz="0.060261"/>
      </inertial>
      <visual name="visual1">
         <geometry>
            <mesh filename="Geometry/r_pelvis.stl"
                  scale="1.0435593994272849 1.0435593994272849 1.0435593994272849"/>
         </geometry>
         <origin rpy="0 0 0" xyz="0 0 0"/>
         <material name="white">
            <color rgba="1 1 1 1"/>
         </material>
      </visual>
      <visual name="visual2">
         <geometry>
            <mesh filename="Geometry/l_pelvis.stl"
                  scale="1.0435593994272849 1.0435593994272849 1.0435593994272849"/>
         </geometry>
         <origin rpy="0 0 0" xyz="0 0 0"/>
         <material name="white">
            <color rgba="1 1 1 1"/>
         </material>
      </visual>
      <visual name="visual3">
         <geometry>
            <mesh filename="Geometry/sacrum.stl"
                  scale="1.0435593994272849 1.0435593994272849 1.0435593994272849"/>
         </geometry>
         <origin rpy="0 0 0" xyz="0 0 0"/>
         <material name="white">
            <color rgba="1 1 1 1"/>
         </material>
      </visual>
   </link>
   <link name="femur_r">
      <inertial>
         <mass value="8.8894009583604348"/>
         <origin rpy="0 0 0" xyz="0 0 0"/>
         <inertia ixx="0.10614" ixy="0" ixz="0" iyy="0.027823" iyz="0" izz="0.11193"/>
      </inertial>
      <visual name="visual1">
         <geometry>
            <mesh filename="Geometry/r_femur.stl"
                  scale="0.91072311572106535 0.91072311572106535 0.91072311572106535"/>
         </geometry>
         <origin rpy="0 0 0" xyz="0 0 0"/>
         <material name="white">
            <color rgba="1 1 1 1"/>
         </material>
      </visual>
      <collision>
         <origin rpy="1.57 0 0" xyz="0.000000 -0.182145 0.018214"/>
         <geometry>
            <capsule length="0.295985" radius="0.013661"/>
         </geometry>
      </collision>
   </link>
   <link name="tibia_r">
      <inertial>
         <mass value="3.5432788669578033"/>
         <origin rpy="0 0 0" xyz="0 0 0"/>
         <inertia ixx="0.043547" ixy="0" ixz="0" iyy="0.0044065" iyz="0" izz="0.044152"/>
      </inertial>
      <visual name="visual1">
         <geometry>
            <mesh filename="Geometry/r_tibia.stl"
                  scale="0.95082459939672426 0.95082459939672426 0.95082459939672426"/>
         </geometry>
         <origin rpy="0 0 0" xyz="0 0 0"/>
         <material name="white">
            <color rgba="1 1 1 1"/>
         </material>
      </visual>
      <collision>
         <origin rpy="1.57 0 0" xyz="0.000000 -0.142624 0.019016"/>
         <geometry>
            <capsule length="0.261477" radius="0.014262"/>
         </geometry>
      </collision>
      <visual name="visual2">
         <geometry>
            <mesh filename="Geometry/r_fibula.stl"
                  scale="0.95082459939672426 0.95082459939672426 0.95082459939672426"/>
         </geometry>
         <origin rpy="0 0 0" xyz="0 0 0"/>
         <material name="white">
            <color rgba="1 1 1 1"/>
         </material>
      </visual>
      <collision>
         <origin rpy="1.57 0 0" xyz="0.000000 -0.142624 0.019016"/>
         <geometry>
            <capsule length="0.261477" radius="0.014262"/>
         </geometry>
      </collision>
   </link>
   <link name="patella_r">
      <inertial>
         <mass value="0.082381830972828765"/>
         <origin rpy="0 0 0" xyz="0 0 0"/>
         <inertia ixx="2.7429e-06" ixy="0" ixz="0" iyy="1.2529e-05" iyz="0" izz="1.2529e-05"/>
      </inertial>
   </link>
   <link name="talus_r">
      <inertial>
         <mass value="0.095570569574047304"/>
         <origin rpy="0 0 0" xyz="0 0 0"/>
         <inertia ixx="0.00062454" ixy="0" ixz="0" iyy="0.00062454" iyz="0" izz="0.00062454"/>
      </inertial>
      <visual name="visual1">
         <geometry>
            <mesh filename="Geometry/r_talus.stl"
                  scale="0.80838540372881895 0.80838540372881895 0.80838540372881895"/>
         </geometry>
         <origin rpy="0 0 0" xyz="0 0 0"/>
         <material name="white">
            <color rgba="1 1 1 1"/>
         </material>
      </visual>
   </link>
   <link name="calcn_r">
      <inertial>
         <mass value="1.1946321196755911"/>
         <origin rpy="0 0 0" xyz="0 0 0"/>
         <inertia ixx="0.00087436" ixy="0" ixz="0" iyy="0.0024357" iyz="0" izz="0.0025606"/>
      </inertial>
      <visual name="visual1">
         <geometry>
            <mesh filename="Geometry/r_foot.stl"
                  scale="0.80838540372881895 0.80838540372881895 0.80838540372881895"/>
         </geometry>
         <origin rpy="0 0 0" xyz="0 0 0"/>
         <material name="white">
            <color rgba="1 1 1 1"/>
         </material>
      </visual>
      <collision>
         <origin rpy="0 0 0" xyz="0.024252 0.016168 0.000000"/>
         <geometry>
            <sphere radius="0.040419"/>
         </geometry>
      </collision>
   </link>
   <link name="toes_r">
      <inertial>
         <mass value="0.20700585369738642"/>
         <origin rpy="0 0 0" xyz="0 0 0"/>
         <inertia ixx="6.2454e-05" ixy="0" ixz="0" iyy="0.00012491" iyz="0" izz="0.00062454"/>
      </inertial>
      <visual name="visual1">
         <geometry>
            <mesh filename="Geometry/r_bofoot.stl"
                  scale="0.80838540372881895 0.80838540372881895 0.80838540372881895"/>
         </geometry>
         <origin rpy="0 0 0" xyz="0 0 0"/>
         <material name="white">
            <color rgba="1 1 1 1"/>
         </material>
      </visual>
      <collision>
         <origin rpy="0 0 0" xyz="0.016168 -0.004042 -0.021018"/>
         <geometry>
            <sphere radius="0.020210"/>
         </geometry>
      </collision>
      <collision>
         <origin rpy="0 0 0" xyz="0.016168 -0.004042 0.021018"/>
         <geometry>
            <sphere radius="0.020210"/>
         </geometry>
      </collision>
   </link>
   <link name="femur_l">
      <inertial>
         <mass value="8.8894009583604348"/>
         <origin rpy="0 0 0" xyz="0 0 0"/>
         <inertia ixx="0.10614" ixy="0" ixz="0" iyy="0.027823" iyz="0" izz="0.11193"/>
      </inertial>
      <visual name="visual1">
         <geometry>
            <mesh filename="Geometry/l_femur.stl"
                  scale="0.91072311572106535 0.91072311572106535 0.91072311572106535"/>
         </geometry>
         <origin rpy="0 0 0" xyz="0 0 0"/>
         <material name="white">
            <color rgba="1 1 1 1"/>
         </material>
      </visual>
      <collision>
         <origin rpy="1.57 0 0" xyz="0.000000 -0.182145 -0.018214"/>
         <geometry>
            <capsule length="0.295985" radius="0.013661"/>
         </geometry>
      </collision>
   </link>
   <link name="tibia_l">
      <inertial>
         <mass value="3.5432788669578033"/>
         <origin rpy="0 0 0" xyz="0 0 0"/>
         <inertia ixx="0.043547" ixy="0" ixz="0" iyy="0.0044065" iyz="0" izz="0.044152"/>
      </inertial>
      <visual name="visual1">
         <geometry>
            <mesh filename="Geometry/l_tibia.stl"
                  scale="0.95082459939672426 0.95082459939672426 0.95082459939672426"/>
         </geometry>
         <origin rpy="0 0 0" xyz="0 0 0"/>
         <material name="white">
            <color rgba="1 1 1 1"/>
         </material>
      </visual>
      <collision>
         <origin rpy="1.57 0 0" xyz="0.000000 -0.142624 -0.019016"/>
         <geometry>
            <capsule length="0.261477" radius="0.014262"/>
         </geometry>
      </collision>
      <visual name="visual2">
         <geometry>
            <mesh filename="Geometry/l_fibula.stl"
                  scale="0.95082459939672426 0.95082459939672426 0.95082459939672426"/>
         </geometry>
         <origin rpy="0 0 0" xyz="0 0 0"/>
         <material name="white">
            <color rgba="1 1 1 1"/>
         </material>
      </visual>
      <collision>
         <origin rpy="1.57 0 0" xyz="0.000000 -0.142624 -0.019016"/>
         <geometry>
            <capsule length="0.261477" radius="0.014262"/>
         </geometry>
      </collision>
   </link>
   <link name="patella_l">
      <inertial>
         <mass value="0.082381830972828765"/>
         <origin rpy="0 0 0" xyz="0 0 0"/>
         <inertia ixx="2.7429e-06" ixy="0" ixz="0" iyy="1.2529e-05" iyz="0" izz="1.2529e-05"/>
      </inertial>
   </link>
   <link name="talus_l">
      <inertial>
         <mass value="0.095570569574047304"/>
         <origin rpy="0 0 0" xyz="0 0 0"/>
         <inertia ixx="0.00062454" ixy="0" ixz="0" iyy="0.00062454" iyz="0" izz="0.00062454"/>
      </inertial>
      <visual name="visual1">
         <geometry>
            <mesh filename="Geometry/l_talus.stl"
                  scale="0.80838540372881895 0.80838540372881895 0.80838540372881895"/>
         </geometry>
         <origin rpy="0 0 0" xyz="0 0 0"/>
         <material name="white">
            <color rgba="1 1 1 1"/>
         </material>
      </visual>
   </link>
   <link name="calcn_l">
      <inertial>
         <mass value="1.1946321196755911"/>
         <origin rpy="0 0 0" xyz="0 0 0"/>
         <inertia ixx="0.00087436" ixy="0" ixz="0" iyy="0.0024357" iyz="0" izz="0.0025606"/>
      </inertial>
      <visual name="visual1">
         <geometry>
            <mesh filename="Geometry/l_foot.stl"
                  scale="0.80838540372881895 0.80838540372881895 0.80838540372881895"/>
         </geometry>
         <origin rpy="0 0 0" xyz="0 0 0"/>
         <material name="white">
            <color rgba="1 1 1 1"/>
         </material>
      </visual>
      <collision>
         <origin rpy="0 0 0" xyz="0.024252 0.016168 0.000000"/>
         <geometry>
            <sphere radius="0.040419"/>
         </geometry>
      </collision>
   </link>
   <link name="toes_l">
      <inertial>
         <mass value="0.20700585369738642"/>
         <origin rpy="0 0 0" xyz="0 0 0"/>
         <inertia ixx="6.2454e-05" ixy="0" ixz="0" iyy="0.00012491" iyz="0" izz="0.00062454"/>
      </inertial>
      <visual name="visual1">
         <geometry>
            <mesh filename="Geometry/l_bofoot.stl"
                  scale="0.80838540372881895 0.80838540372881895 0.80838540372881895"/>
         </geometry>
         <origin rpy="0 0 0" xyz="0 0 0"/>
         <material name="white">
            <color rgba="1 1 1 1"/>
         </material>
      </visual>
      <collision>
         <origin rpy="0 0 0" xyz="0.016168 -0.004042 -0.021018"/>
         <geometry>
            <sphere radius="0.020210"/>
         </geometry>
      </collision>
      <collision>
         <origin rpy="0 0 0" xyz="0.016168 -0.004042 0.021018"/>
         <geometry>
            <sphere radius="0.020210"/>
         </geometry>
      </collision>
   </link>
   <link name="torso">
      <inertial>
         <mass value="25.63833441735137"/>
         <origin rpy="0 0 0" xyz="0 0 0"/>
         <inertia ixx="1.5484" ixy="0" ixz="0" iyy="0.79339" iyz="0" izz="1.5032"/>
      </inertial>
      <visual name="visual1">
         <geometry>
            <mesh filename="Geometry/hat_spine.stl"
                  scale="1.0482473418552212 1.0482473418552212 1.0482473418552212"/>
         </geometry>
         <origin rpy="0 0 0" xyz="0 0 0"/>
         <material name="white">
            <color rgba="1 1 1 1"/>
         </material>
      </visual>
      <visual name="visual2">
         <geometry>
            <mesh filename="Geometry/hat_jaw.stl"
                  scale="1.0482473418552212 1.0482473418552212 1.0482473418552212"/>
         </geometry>
         <origin rpy="0 0 0" xyz="0 0 0"/>
         <material name="white">
            <color rgba="1 1 1 1"/>
         </material>
      </visual>
      <visual name="visual3">
         <geometry>
            <mesh filename="Geometry/hat_skull.stl"
                  scale="1.0482473418552212 1.0482473418552212 1.0482473418552212"/>
         </geometry>
         <origin rpy="0 0 0" xyz="0 0 0"/>
         <material name="white">
            <color rgba="1 1 1 1"/>
         </material>
      </visual>
      <visual name="visual4">
         <geometry>
            <mesh filename="Geometry/hat_ribs_scap.stl"
                  scale="1.0482473418552212 1.0482473418552212 1.0482473418552212"/>
         </geometry>
         <origin rpy="0 0 0" xyz="0 0 0"/>
         <material name="white">
            <color rgba="1 1 1 1"/>
         </material>
      </visual>
   </link>
   <link name="humerus_r">
      <inertial>
         <mass value="1.9424718265925114"/>
         <origin rpy="0 0 0" xyz="0 0 0"/>
         <inertia ixx="0.0095019" ixy="0" ixz="0" iyy="0.0032779" iyz="0" izz="0.010666"/>
      </inertial>
      <visual name="visual1">
         <geometry>
            <mesh filename="Geometry/humerus_rv.stl"
                  scale="0.91228631042150732 0.91228631042150732 0.91228631042150732"/>
         </geometry>
         <origin rpy="0 0 0" xyz="0 0 0"/>
         <material name="white">
            <color rgba="1 1 1 1"/>
         </material>
      </visual>
   </link>
   <link name="ulna_r">
      <inertial>
         <mass value="0.58059121016233739"/>
         <origin rpy="0 0 0" xyz="0 0 0"/>
         <inertia ixx="0.0028768" ixy="0" ixz="0" iyy="0.00060022" iyz="0" izz="0.0031206"/>
      </inertial>
      <visual name="visual1">
         <geometry>
            <mesh filename="Geometry/ulna_rv.stl"
                  scale="1.0080897692215547 1.0080897692215547 1.0080897692215547"/>
         </geometry>
         <origin rpy="0 0 0" xyz="0 0 0"/>
         <material name="white">
            <color rgba="1 1 1 1"/>
         </material>
      </visual>
   </link>
   <link name="radius_r">
      <inertial>
         <mass value="0.58059121016233739"/>
         <origin rpy="0 0 0" xyz="0 0 0"/>
         <inertia ixx="0.0028768" ixy="0" ixz="0" iyy="0.00060022" iyz="0" izz="0.0031206"/>
      </inertial>
      <visual name="visual1">
         <geometry>
            <mesh filename="Geometry/radius_rv.stl"
                  scale="1.0080897692215547 1.0080897692215547 1.0080897692215547"/>
         </geometry>
         <origin rpy="0 0 0" xyz="0 0 0"/>
         <material name="white">
            <color rgba="1 1 1 1"/>
         </material>
      </visual>
   </link>
   <link name="hand_r">
      <inertial>
         <mass value="0.43723535580126638"/>
         <origin rpy="0 0 0" xyz="0 0 0"/>
         <inertia ixx="0.0009176" ixy="0" ixz="0" iyy="0.0005627" iyz="0" izz="0.0013785"/>
      </inertial>
      <visual name="visual1">
         <geometry>
            <mesh filename="Geometry/pisiform_rvs.stl"
                  scale="0.88186237330683181 0.88186237330683181 0.88186237330683181"/>
         </geometry>
         <origin rpy="0 0 0" xyz="0 0 0"/>
         <material name="white">
            <color rgba="1 1 1 1"/>
         </material>
      </visual>
      <visual name="visual2">
         <geometry>
            <mesh filename="Geometry/lunate_rvs.stl"
                  scale="0.88186237330683181 0.88186237330683181 0.88186237330683181"/>
         </geometry>
         <origin rpy="0 0 0" xyz="0 0 0"/>
         <material name="white">
            <color rgba="1 1 1 1"/>
         </material>
      </visual>
      <visual name="visual3">
         <geometry>
            <mesh filename="Geometry/scaphoid_rvs.stl"
                  scale="0.88186237330683181 0.88186237330683181 0.88186237330683181"/>
         </geometry>
         <origin rpy="0 0 0" xyz="0 0 0"/>
         <material name="white">
            <color rgba="1 1 1 1"/>
         </material>
      </visual>
      <visual name="visual4">
         <geometry>
            <mesh filename="Geometry/triquetrum_rvs.stl"
                  scale="0.88186237330683181 0.88186237330683181 0.88186237330683181"/>
         </geometry>
         <origin rpy="0 0 0" xyz="0 0 0"/>
         <material name="white">
            <color rgba="1 1 1 1"/>
         </material>
      </visual>
      <visual name="visual5">
         <geometry>
            <mesh filename="Geometry/hamate_rvs.stl"
                  scale="0.88186237330683181 0.88186237330683181 0.88186237330683181"/>
         </geometry>
         <origin rpy="0 0 0" xyz="0 0 0"/>
         <material name="white">
            <color rgba="1 1 1 1"/>
         </material>
      </visual>
      <visual name="visual6">
         <geometry>
            <mesh filename="Geometry/capitate_rvs.stl"
                  scale="0.88186237330683181 0.88186237330683181 0.88186237330683181"/>
         </geometry>
         <origin rpy="0 0 0" xyz="0 0 0"/>
         <material name="white">
            <color rgba="1 1 1 1"/>
         </material>
      </visual>
      <visual name="visual7">
         <geometry>
            <mesh filename="Geometry/trapezoid_rvs.stl"
                  scale="0.88186237330683181 0.88186237330683181 0.88186237330683181"/>
         </geometry>
         <origin rpy="0 0 0" xyz="0 0 0"/>
         <material name="white">
            <color rgba="1 1 1 1"/>
         </material>
      </visual>
      <visual name="visual8">
         <geometry>
            <mesh filename="Geometry/trapezium_rvs.stl"
                  scale="0.88186237330683181 0.88186237330683181 0.88186237330683181"/>
         </geometry>
         <origin rpy="0 0 0" xyz="0 0 0"/>
         <material name="white">
            <color rgba="1 1 1 1"/>
         </material>
      </visual>
      <visual name="visual9">
         <geometry>
            <mesh filename="Geometry/metacarpal2_rvs.stl"
                  scale="0.88186237330683181 0.88186237330683181 0.88186237330683181"/>
         </geometry>
         <origin rpy="0 0 0" xyz="0 0 0"/>
         <material name="white">
            <color rgba="1 1 1 1"/>
         </material>
      </visual>
      <visual name="visual10">
         <geometry>
            <mesh filename="Geometry/index_proximal_rvs.stl"
                  scale="0.88186237330683181 0.88186237330683181 0.88186237330683181"/>
         </geometry>
         <origin rpy="0 0 0" xyz="0 0 0"/>
         <material name="white">
            <color rgba="1 1 1 1"/>
         </material>
      </visual>
      <visual name="visual11">
         <geometry>
            <mesh filename="Geometry/index_medial_rvs.stl"
                  scale="0.88186237330683181 0.88186237330683181 0.88186237330683181"/>
         </geometry>
         <origin rpy="0 0 0" xyz="0 0 0"/>
         <material name="white">
            <color rgba="1 1 1 1"/>
         </material>
      </visual>
      <visual name="visual12">
         <geometry>
            <mesh filename="Geometry/index_distal_rvs.stl"
                  scale="0.88186237330683181 0.88186237330683181 0.88186237330683181"/>
         </geometry>
         <origin rpy="0 0 0" xyz="0 0 0"/>
         <material name="white">
            <color rgba="1 1 1 1"/>
         </material>
      </visual>
      <visual name="visual13">
         <geometry>
            <mesh filename="Geometry/metacarpal3_rvs.stl"
                  scale="0.88186237330683181 0.88186237330683181 0.88186237330683181"/>
         </geometry>
         <origin rpy="0 0 0" xyz="0 0 0"/>
         <material name="white">
            <color rgba="1 1 1 1"/>
         </material>
      </visual>
      <visual name="visual14">
         <geometry>
            <mesh filename="Geometry/middle_proximal_rvs.stl"
                  scale="0.88186237330683181 0.88186237330683181 0.88186237330683181"/>
         </geometry>
         <origin rpy="0 0 0" xyz="0 0 0"/>
         <material name="white">
            <color rgba="1 1 1 1"/>
         </material>
      </visual>
      <visual name="visual15">
         <geometry>
            <mesh filename="Geometry/middle_medial_rvs.stl"
                  scale="0.88186237330683181 0.88186237330683181 0.88186237330683181"/>
         </geometry>
         <origin rpy="0 0 0" xyz="0 0 0"/>
         <material name="white">
            <color rgba="1 1 1 1"/>
         </material>
      </visual>
      <visual name="visual16">
         <geometry>
            <mesh filename="Geometry/middle_distal_rvs.stl"
                  scale="0.88186237330683181 0.88186237330683181 0.88186237330683181"/>
         </geometry>
         <origin rpy="0 0 0" xyz="0 0 0"/>
         <material name="white">
            <color rgba="1 1 1 1"/>
         </material>
      </visual>
      <visual name="visual17">
         <geometry>
            <mesh filename="Geometry/metacarpal4_rvs.stl"
                  scale="0.88186237330683181 0.88186237330683181 0.88186237330683181"/>
         </geometry>
         <origin rpy="0 0 0" xyz="0 0 0"/>
         <material name="white">
            <color rgba="1 1 1 1"/>
         </material>
      </visual>
      <visual name="visual18">
         <geometry>
            <mesh filename="Geometry/ring_proximal_rvs.stl"
                  scale="0.88186237330683181 0.88186237330683181 0.88186237330683181"/>
         </geometry>
         <origin rpy="0 0 0" xyz="0 0 0"/>
         <material name="white">
            <color rgba="1 1 1 1"/>
         </material>
      </visual>
      <visual name="visual19">
         <geometry>
            <mesh filename="Geometry/ring_medial_rvs.stl"
                  scale="0.88186237330683181 0.88186237330683181 0.88186237330683181"/>
         </geometry>
         <origin rpy="0 0 0" xyz="0 0 0"/>
         <material name="white">
            <color rgba="1 1 1 1"/>
         </material>
      </visual>
      <visual name="visual20">
         <geometry>
            <mesh filename="Geometry/ring_distal_rvs.stl"
                  scale="0.88186237330683181 0.88186237330683181 0.88186237330683181"/>
         </geometry>
         <origin rpy="0 0 0" xyz="0 0 0"/>
         <material name="white">
            <color rgba="1 1 1 1"/>
         </material>
      </visual>
      <visual name="visual21">
         <geometry>
            <mesh filename="Geometry/metacarpal5_rvs.stl"
                  scale="0.88186237330683181 0.88186237330683181 0.88186237330683181"/>
         </geometry>
         <origin rpy="0 0 0" xyz="0 0 0"/>
         <material name="white">
            <color rgba="1 1 1 1"/>
         </material>
      </visual>
      <visual name="visual22">
         <geometry>
            <mesh filename="Geometry/little_proximal_rvs.stl"
                  scale="0.88186237330683181 0.88186237330683181 0.88186237330683181"/>
         </geometry>
         <origin rpy="0 0 0" xyz="0 0 0"/>
         <material name="white">
            <color rgba="1 1 1 1"/>
         </material>
      </visual>
      <visual name="visual23">
         <geometry>
            <mesh filename="Geometry/little_medial_rvs.stl"
                  scale="0.88186237330683181 0.88186237330683181 0.88186237330683181"/>
         </geometry>
         <origin rpy="0 0 0" xyz="0 0 0"/>
         <material name="white">
            <color rgba="1 1 1 1"/>
         </material>
      </visual>
      <visual name="visual24">
         <geometry>
            <mesh filename="Geometry/little_distal_rvs.stl"
                  scale="0.88186237330683181 0.88186237330683181 0.88186237330683181"/>
         </geometry>
         <origin rpy="0 0 0" xyz="0 0 0"/>
         <material name="white">
            <color rgba="1 1 1 1"/>
         </material>
      </visual>
      <visual name="visual25">
         <geometry>
            <mesh filename="Geometry/metacarpal1_rvs.stl"
                  scale="0.88186237330683181 0.88186237330683181 0.88186237330683181"/>
         </geometry>
         <origin rpy="0 0 0" xyz="0 0 0"/>
         <material name="white">
            <color rgba="1 1 1 1"/>
         </material>
      </visual>
      <visual name="visual26">
         <geometry>
            <mesh filename="Geometry/thumb_proximal_rvs.stl"
                  scale="0.88186237330683181 0.88186237330683181 0.88186237330683181"/>
         </geometry>
         <origin rpy="0 0 0" xyz="0 0 0"/>
         <material name="white">
            <color rgba="1 1 1 1"/>
         </material>
      </visual>
      <visual name="visual27">
         <geometry>
            <mesh filename="Geometry/thumb_distal_rvs.stl"
                  scale="0.88186237330683181 0.88186237330683181 0.88186237330683181"/>
         </geometry>
         <origin rpy="0 0 0" xyz="0 0 0"/>
         <material name="white">
            <color rgba="1 1 1 1"/>
         </material>
      </visual>
   </link>
   <link name="humerus_l">
      <inertial>
         <mass value="1.9424718265925114"/>
         <origin rpy="0 0 0" xyz="0 0 0"/>
         <inertia ixx="0.0095019" ixy="0" ixz="0" iyy="0.0032779" iyz="0" izz="0.010666"/>
      </inertial>
      <visual name="visual1">
         <geometry>
            <mesh filename="Geometry/humerus_lv.stl"
                  scale="0.91228631042150732 0.91228631042150732 0.91228631042150732"/>
         </geometry>
         <origin rpy="0 0 0" xyz="0 0 0"/>
         <material name="white">
            <color rgba="1 1 1 1"/>
         </material>
      </visual>
   </link>
   <link name="ulna_l">
      <inertial>
         <mass value="0.58059121016233739"/>
         <origin rpy="0 0 0" xyz="0 0 0"/>
         <inertia ixx="0.0028768" ixy="0" ixz="0" iyy="0.00060022" iyz="0" izz="0.0031206"/>
      </inertial>
      <visual name="visual1">
         <geometry>
            <mesh filename="Geometry/ulna_lv.stl"
                  scale="1.0080897692215547 1.0080897692215547 1.0080897692215547"/>
         </geometry>
         <origin rpy="0 0 0" xyz="0 0 0"/>
         <material name="white">
            <color rgba="1 1 1 1"/>
         </material>
      </visual>
   </link>
   <link name="radius_l">
      <inertial>
         <mass value="0.58059121016233739"/>
         <origin rpy="0 0 0" xyz="0 0 0"/>
         <inertia ixx="0.0028768" ixy="0" ixz="0" iyy="0.00060022" iyz="0" izz="0.0031206"/>
      </inertial>
      <visual name="visual1">
         <geometry>
            <mesh filename="Geometry/radius_lv.stl"
                  scale="1.0080897692215547 1.0080897692215547 1.0080897692215547"/>
         </geometry>
         <origin rpy="0 0 0" xyz="0 0 0"/>
         <material name="white">
            <color rgba="1 1 1 1"/>
         </material>
      </visual>
   </link>
   <link name="hand_l">
      <inertial>
         <mass value="0.43723535580126638"/>
         <origin rpy="0 0 0" xyz="0 0 0"/>
         <inertia ixx="0.0009176" ixy="0" ixz="0" iyy="0.0005627" iyz="0" izz="0.0013785"/>
      </inertial>
      <visual name="visual1">
         <geometry>
            <mesh filename="Geometry/pisiform_lvs.stl"
                  scale="0.88186237330683181 0.88186237330683181 0.88186237330683181"/>
         </geometry>
         <origin rpy="0 0 0" xyz="0 0 0"/>
         <material name="white">
            <color rgba="1 1 1 1"/>
         </material>
      </visual>
      <visual name="visual2">
         <geometry>
            <mesh filename="Geometry/lunate_lvs.stl"
                  scale="0.88186237330683181 0.88186237330683181 0.88186237330683181"/>
         </geometry>
         <origin rpy="0 0 0" xyz="0 0 0"/>
         <material name="white">
            <color rgba="1 1 1 1"/>
         </material>
      </visual>
      <visual name="visual3">
         <geometry>
            <mesh filename="Geometry/scaphoid_lvs.stl"
                  scale="0.88186237330683181 0.88186237330683181 0.88186237330683181"/>
         </geometry>
         <origin rpy="0 0 0" xyz="0 0 0"/>
         <material name="white">
            <color rgba="1 1 1 1"/>
         </material>
      </visual>
      <visual name="visual4">
         <geometry>
            <mesh filename="Geometry/triquetrum_lvs.stl"
                  scale="0.88186237330683181 0.88186237330683181 0.88186237330683181"/>
         </geometry>
         <origin rpy="0 0 0" xyz="0 0 0"/>
         <material name="white">
            <color rgba="1 1 1 1"/>
         </material>
      </visual>
      <visual name="visual5">
         <geometry>
            <mesh filename="Geometry/hamate_lvs.stl"
                  scale="0.88186237330683181 0.88186237330683181 0.88186237330683181"/>
         </geometry>
         <origin rpy="0 0 0" xyz="0 0 0"/>
         <material name="white">
            <color rgba="1 1 1 1"/>
         </material>
      </visual>
      <visual name="visual6">
         <geometry>
            <mesh filename="Geometry/capitate_lvs.stl"
                  scale="0.88186237330683181 0.88186237330683181 0.88186237330683181"/>
         </geometry>
         <origin rpy="0 0 0" xyz="0 0 0"/>
         <material name="white">
            <color rgba="1 1 1 1"/>
         </material>
      </visual>
      <visual name="visual7">
         <geometry>
            <mesh filename="Geometry/trapezoid_lvs.stl"
                  scale="0.88186237330683181 0.88186237330683181 0.88186237330683181"/>
         </geometry>
         <origin rpy="0 0 0" xyz="0 0 0"/>
         <material name="white">
            <color rgba="1 1 1 1"/>
         </material>
      </visual>
      <visual name="visual8">
         <geometry>
            <mesh filename="Geometry/trapezium_lvs.stl"
                  scale="0.88186237330683181 0.88186237330683181 0.88186237330683181"/>
         </geometry>
         <origin rpy="0 0 0" xyz="0 0 0"/>
         <material name="white">
            <color rgba="1 1 1 1"/>
         </material>
      </visual>
      <visual name="visual9">
         <geometry>
            <mesh filename="Geometry/metacarpal2_lvs.stl"
                  scale="0.88186237330683181 0.88186237330683181 0.88186237330683181"/>
         </geometry>
         <origin rpy="0 0 0" xyz="0 0 0"/>
         <material name="white">
            <color rgba="1 1 1 1"/>
         </material>
      </visual>
      <visual name="visual10">
         <geometry>
            <mesh filename="Geometry/index_proximal_lvs.stl"
                  scale="0.88186237330683181 0.88186237330683181 0.88186237330683181"/>
         </geometry>
         <origin rpy="0 0 0" xyz="0 0 0"/>
         <material name="white">
            <color rgba="1 1 1 1"/>
         </material>
      </visual>
      <visual name="visual11">
         <geometry>
            <mesh filename="Geometry/index_medial_lvs.stl"
                  scale="0.88186237330683181 0.88186237330683181 0.88186237330683181"/>
         </geometry>
         <origin rpy="0 0 0" xyz="0 0 0"/>
         <material name="white">
            <color rgba="1 1 1 1"/>
         </material>
      </visual>
      <visual name="visual12">
         <geometry>
            <mesh filename="Geometry/index_distal_lvs.stl"
                  scale="0.88186237330683181 0.88186237330683181 0.88186237330683181"/>
         </geometry>
         <origin rpy="0 0 0" xyz="0 0 0"/>
         <material name="white">
            <color rgba="1 1 1 1"/>
         </material>
      </visual>
      <visual name="visual13">
         <geometry>
            <mesh filename="Geometry/metacarpal3_lvs.stl"
                  scale="0.88186237330683181 0.88186237330683181 0.88186237330683181"/>
         </geometry>
         <origin rpy="0 0 0" xyz="0 0 0"/>
         <material name="white">
            <color rgba="1 1 1 1"/>
         </material>
      </visual>
      <visual name="visual14">
         <geometry>
            <mesh filename="Geometry/middle_proximal_lvs.stl"
                  scale="0.88186237330683181 0.88186237330683181 0.88186237330683181"/>
         </geometry>
         <origin rpy="0 0 0" xyz="0 0 0"/>
         <material name="white">
            <color rgba="1 1 1 1"/>
         </material>
      </visual>
      <visual name="visual15">
         <geometry>
            <mesh filename="Geometry/middle_medial_lvs.stl"
                  scale="0.88186237330683181 0.88186237330683181 0.88186237330683181"/>
         </geometry>
         <origin rpy="0 0 0" xyz="0 0 0"/>
         <material name="white">
            <color rgba="1 1 1 1"/>
         </material>
      </visual>
      <visual name="visual16">
         <geometry>
            <mesh filename="Geometry/middle_distal_lvs.stl"
                  scale="0.88186237330683181 0.88186237330683181 0.88186237330683181"/>
         </geometry>
         <origin rpy="0 0 0" xyz="0 0 0"/>
         <material name="white">
            <color rgba="1 1 1 1"/>
         </material>
      </visual>
      <visual name="visual17">
         <geometry>
            <mesh filename="Geometry/metacarpal4_lvs.stl"
                  scale="0.88186237330683181 0.88186237330683181 0.88186237330683181"/>
         </geometry>
         <origin rpy="0 0 0" xyz="0 0 0"/>
         <material name="white">
            <color rgba="1 1 1 1"/>
         </material>
      </visual>
      <visual name="visual18">
         <geometry>
            <mesh filename="Geometry/ring_proximal_lvs.stl"
                  scale="0.88186237330683181 0.88186237330683181 0.88186237330683181"/>
         </geometry>
         <origin rpy="0 0 0" xyz="0 0 0"/>
         <material name="white">
            <color rgba="1 1 1 1"/>
         </material>
      </visual>
      <visual name="visual19">
         <geometry>
            <mesh filename="Geometry/ring_medial_lvs.stl"
                  scale="0.88186237330683181 0.88186237330683181 0.88186237330683181"/>
         </geometry>
         <origin rpy="0 0 0" xyz="0 0 0"/>
         <material name="white">
            <color rgba="1 1 1 1"/>
         </material>
      </visual>
      <visual name="visual20">
         <geometry>
            <mesh filename="Geometry/ring_distal_lvs.stl"
                  scale="0.88186237330683181 0.88186237330683181 0.88186237330683181"/>
         </geometry>
         <origin rpy="0 0 0" xyz="0 0 0"/>
         <material name="white">
            <color rgba="1 1 1 1"/>
         </material>
      </visual>
      <visual name="visual21">
         <geometry>
            <mesh filename="Geometry/metacarpal5_lvs.stl"
                  scale="0.88186237330683181 0.88186237330683181 0.88186237330683181"/>
         </geometry>
         <origin rpy="0 0 0" xyz="0 0 0"/>
         <material name="white">
            <color rgba="1 1 1 1"/>
         </material>
      </visual>
      <visual name="visual22">
         <geometry>
            <mesh filename="Geometry/little_proximal_lvs.stl"
                  scale="0.88186237330683181 0.88186237330683181 0.88186237330683181"/>
         </geometry>
         <origin rpy="0 0 0" xyz="0 0 0"/>
         <material name="white">
            <color rgba="1 1 1 1"/>
         </material>
      </visual>
      <visual name="visual23">
         <geometry>
            <mesh filename="Geometry/little_medial_lvs.stl"
                  scale="0.88186237330683181 0.88186237330683181 0.88186237330683181"/>
         </geometry>
         <origin rpy="0 0 0" xyz="0 0 0"/>
         <material name="white">
            <color rgba="1 1 1 1"/>
         </material>
      </visual>
      <visual name="visual24">
         <geometry>
            <mesh filename="Geometry/little_distal_lvs.stl"
                  scale="0.88186237330683181 0.88186237330683181 0.88186237330683181"/>
         </geometry>
         <origin rpy="0 0 0" xyz="0 0 0"/>
         <material name="white">
            <color rgba="1 1 1 1"/>
         </material>
      </visual>
      <visual name="visual25">
         <geometry>
            <mesh filename="Geometry/metacarpal1_lvs.stl"
                  scale="0.88186237330683181 0.88186237330683181 0.88186237330683181"/>
         </geometry>
         <origin rpy="0 0 0" xyz="0 0 0"/>
         <material name="white">
            <color rgba="1 1 1 1"/>
         </material>
      </visual>
      <visual name="visual26">
         <geometry>
            <mesh filename="Geometry/thumb_proximal_lvs.stl"
                  scale="0.88186237330683181 0.88186237330683181 0.88186237330683181"/>
         </geometry>
         <origin rpy="0 0 0" xyz="0 0 0"/>
         <material name="white">
            <color rgba="1 1 1 1"/>
         </material>
      </visual>
      <visual name="visual27">
         <geometry>
            <mesh filename="Geometry/thumb_distal_lvs.stl"
                  scale="0.88186237330683181 0.88186237330683181 0.88186237330683181"/>
         </geometry>
         <origin rpy="0 0 0" xyz="0 0 0"/>
         <material name="white">
            <color rgba="1 1 1 1"/>
         </material>
      </visual>
   </link>
   <joint name="back" type="spherical">
      <origin rpy="0. 0. 0." xyz="-0.105086 0.085050 0.000000"/>
      <parent link="pelvis"/>
      <child link="torso"/>
      <axis xyz="0 0 1"/>
      <limit effort="400" lower="1.57"/>
   </joint>
   <joint name="acromial_r" type="spherical">
      <origin rpy="0. 0. 0." xyz="0.003307 0.389424 0.178202"/>
      <parent link="torso"/>
      <child link="humerus_r"/>
      <axis xyz="0 0 1"/>
      <limit effort="100" lower="1.57"/>
   </joint>
   <joint name="elbow_r" type="revolute">
      <origin rpy="0. 0. 0." xyz="0.011991 -0.261163 -0.008753"/>
      <parent link="humerus_r"/>
      <child link="ulna_r"/>
      <axis xyz="0 0 1"/>
      <limit effort="100" lower="0" upper="3.0"/>
   </joint>
   <joint name="radioulnar_r" type="fixed">
      <origin rpy="0. 1.57 0." xyz="-0.006781 -0.013112 0.026294"/>
      <parent link="ulna_r"/>
      <child link="radius_r"/>
   </joint>
   <joint name="radius_hand_r" type="fixed">
      <origin rpy="0. 0. 0." xyz="-0.008868 -0.237749 0.013720"/>
      <parent link="radius_r"/>
      <child link="hand_r"/>
   </joint>
   <joint name="acromial_l" type="spherical">
      <origin rpy="0. 0. 0." xyz="0.003307 0.389424 -0.178202"/>
      <parent link="torso"/>
      <child link="humerus_l"/>
      <axis xyz="0 0 1"/>
      <limit effort="100" lower="1.57"/>
   </joint>
   <joint name="elbow_l" type="revolute">
      <origin rpy="0. 0. 0." xyz="0.011991 -0.261163 0.008753"/>
      <parent link="humerus_l"/>
      <child link="ulna_l"/>
      <axis xyz="0 0 1"/>
      <limit effort="100" lower="0" upper="3.0"/>
   </joint>
   <joint name="radioulnar_l" type="fixed">
      <origin rpy="0. -1.57 0." xyz="-0.006781 -0.013112 -0.026294"/>
      <parent link="ulna_l"/>
      <child link="radius_l"/>
   </joint>
   <joint name="radius_hand_l" type="fixed">
      <origin rpy="0. 0. 0." xyz="-0.008868 -0.237749 -0.013720"/>
      <parent link="radius_l"/>
      <child link="hand_l"/>
   </joint>
   <joint name="hip_r" type="spherical">
      <origin rpy="0. 0. 0." xyz="-0.058727 -0.081909 0.080625"/>
      <parent link="pelvis"/>
      <child link="femur_r"/>
      <axis xyz="0 0 1"/>
      <limit effort="400.0" lower="2.0"/>
   </joint>
   <joint name="walker_knee_r" type="revolute">
      <origin rpy="0. 0. 0." xyz="-0.000000 -0.368319 -0.001152"/>
      <parent link="femur_r"/>
      <child link="tibia_r"/>
      <axis xyz="0 0 1"/>
      <limit effort="200" lower="-2.2" upper="0"/>
   </joint>
   <joint name="patellofemoral_r" type="fixed">
      <origin rpy="0. 0. 0." xyz="-0.007368 -0.371539 -0.002504"/>
      <parent link="femur_r"/>
      <child link="patella_r"/>
   </joint>
   <joint name="ankle_r" type="revolute">
      <origin rpy="0. 0. 0." xyz="-0.009508 -0.380330 0.000000"/>
      <parent link="tibia_r"/>
      <child link="talus_r"/>
      <axis xyz="0 0 1"/>
      <limit effort="200.0" lower="-0.6981" upper="0.5236"/>
   </joint>
   <joint name="subtalar_r" type="revolute">
      <origin rpy="0. 0. 0." xyz="-0.039425 -0.033912 0.006402"/>
      <parent link="talus_r"/>
      <child link="calcn_r"/>
      <axis xyz="0.78717961000000003 0.60474746000000001 -0.12094949000000001"/>
      <limit effort="200.0" lower="-0.3491" upper="0.3491"/>
   </joint>
   <joint name="mtp_r" type="revolute">
      <origin rpy="0. 0. 0." xyz="0.144539 -0.001617 0.000873"/>
      <parent link="calcn_r"/>
      <child link="toes_r"/>
      <axis xyz="-0.58095439999999998 0 0.81393610999999999"/>
      <limit effort="200.0" lower="-0.5236" upper="0.5236"/>
   </joint>
   <joint name="hip_l" type="spherical">
      <origin rpy="0. 0. 0." xyz="-0.058727 -0.081909 -0.080625"/>
      <parent link="pelvis"/>
      <child link="femur_l"/>
      <axis xyz="0 0 1"/>
      <limit effort="400.0" lower="2.0"/>
   </joint>
   <joint name="walker_knee_l" type="revolute">
      <origin rpy="0. 0. 0." xyz="-0.000000 -0.368319 0.001152"/>
      <parent link="femur_l"/>
      <child link="tibia_l"/>
      <axis xyz="0 0 1"/>
      <limit effort="200" lower="-2.2" upper="0"/>
   </joint>
   <joint name="patellofemoral_l" type="fixed">
      <origin rpy="0. 0. 0." xyz="-0.007368 -0.371539 0.002504"/>
      <parent link="femur_l"/>
      <child link="patella_l"/>
   </joint>
   <joint name="ankle_l" type="revolute">
      <origin rpy="0. 0. 0." xyz="-0.009508 -0.380330 0.000000"/>
      <parent link="tibia_l"/>
      <child link="talus_l"/>
      <axis xyz="0 0 1"/>
      <limit effort="200.0" lower="-0.6981" upper="0.5236"/>
   </joint>
   <joint name="subtalar_l" type="revolute">
      <origin rpy="0. 0. 0." xyz="-0.039425 -0.033912 -0.006402"/>
      <parent link="talus_l"/>
      <child link="calcn_l"/>
      <axis xyz="-0.78717961000000003 -0.60474746000000001 -0.12094949000000001"/>
      <limit effort="200.0" lower="-0.3491" upper="0.3491"/>
   </joint>
   <joint name="mtp_l" type="revolute">
      <origin rpy="0. 0. 0." xyz="0.144539 -0.001617 -0.000873"/>
      <parent link="calcn_l"/>
      <child link="toes_l"/>
      <axis xyz="0.58095439999999998 0 0.81393610999999999"/>
      <limit effort="200.0" lower="-0.5236" upper="0.5236"/>
   </joint>
</robot>